Workbook

Sheet مصفوفة الربط
A1: م | B1: اسم المشروع | C1: هدف البنية المؤسسية المرتبط | D1: هدف التحول الرقمي المرتبط | E1: مبادرة التحول الرقمي المرتبطة | F1: الفجوات المرتبطة | G1: المتطلبات المرتبطة | H1: وصف المشروع | I1: فوائد المشروع | J1: المشاريع المرتبطة | K1: الإدارة المالكة للمشروع | L1: المورد / المقاول | M1: مجال المشروع | N1: طبيعة المشروع (رأسمالي/تشغيلي) | O1: الأولوية | P1: تاريخ بداية المشروع | Q1: تاريخ نهاية المشروع | R1: حالة المشروع | S1: نسبة الإنجاز % | T1: التكلفة (ريال)
A2: 1 | B2: مشروع تجديد رخصة منتجات مايكروسوفت | C2: 2. تعزيز الكفاءة التشغيلية وكفاءة الإنفاق 4. دعم تحسين تجربة المستفيد 5. تعزيز الحوكمة المؤسسية | D2: 1. الامتثال للسياسات ذات العلاقة بمجال البيانات والتحول الرقمي الناشئ من أنظمة الهيئة وخدماتها، ومع تعزيز الاستفادة من البيانات والأنظمة لدعم أعمال الهيئة 5. تحقيق التميز في تقديم الخدمات الرقمية من خلال التوسع في رقمنة الخدمات، وتحسين تجربة المستفيدين بما يضمن الامتثال لمعايير الحكومة الرقمية 6. تنظيم الاستفادة من البنية التحتية التقنية بما يضمن استمرارية الأعمال وحوكمة الكفاءة التشغيلية | E2: ترشيد الإنفاق التقني وإدارة الرخص بفعالية ◂ 2. مبادرة الجاهزية التشغيلية واستمرارية الأعمال | F2: GAP-D-03، GAP-D-11، GAP-D-12، GAP-T-12 | G2: BR18، TR03 | H2: تجديد رخصة مننتجات مايكروسوفت — مشروع تجديد رخصة منتجات مايكروسوفت | I2: ضمان استمرارية دعم الأنظمة الحيوية. الحفاظ على الأمان والتحديثات. الامتثال للمتطلبات القانونية والترخيصية. تقليل مخاطر انقطاع الخدمة أو الثغرات. | J2: • تجديد دعم منتجات مايكروسوفت بريمير ( تجديد عقد ) • مشروع شراء وتجديد رخص البرامج في هيئة تقويم التعليم والتدريب • مشروع تنفيذ بند تشغيل وصيانة البنية التقنية لمنافسة مشروع تشغيل وصيانة البنية التقنية والبيانات وتطبيق الذكاء(تجديد العقد) | K2: الإدارة العامة لتقنية المعلومات | L2: — | M2: التقنية | N2: تشغيلي | O2: متوسطة | P2: 45778 | Q2: 46874 | R2: قائم | S2: 5 | T2: 2500000
A3: 2 | B3: تجديد دعم منتجات مايكروسوفت بريمير ( تجديد عقد ) | C3: 2. تعزيز الكفاءة التشغيلية وكفاءة الإنفاق | D3: 1. الامتثال للسياسات ذات العلاقة بمجال البيانات والتحول الرقمي الناشئ من أنظمة الهيئة وخدماتها، ومع تعزيز الاستفادة من البيانات والأنظمة لدعم أعمال الهيئة 6. تنظيم الاستفادة من البنية التحتية التقنية بما يضمن استمرارية الأعمال وحوكمة الكفاءة التشغيلية | E3: ◂ 2. مبادرة الجاهزية التشغيلية واستمرارية الأعمال | F3: GAP-A-05، GAP-T-12، GAP-T-14 | G3: AR07، BR10، TR03 | H3: تجديد رخص دعم مايكروسوفت بريمير | I3: استمرارية دعم الأنظمة الحيوية • الحفاظ على الأمان والتحديثات • الامتثال للمتطلبات التعاقدية | J3: • مشروع تجديد رخصة منتجات مايكروسوفت • تجديد رخص أنظمة • تأمين خدمة الرسائل النصية لهيئة تقويم التعليم والتدريب (تجديد العقد) | K3: — | L3: — | M3: التقنية | N3: تشغيلي | O3: متوسطة | P3: 46183 | Q3: 47300 | R3: لم يبدأ | S3: 0 | T3: 5000000
A4: 3 | B4: توريد أجهزة الجدار الناري والرخص الخاصة بها | C4: 2. تعزيز الكفاءة التشغيلية وكفاءة الإنفاق | D4: 1. الامتثال للسياسات ذات العلاقة بمجال البيانات والتحول الرقمي الناشئ من أنظمة الهيئة وخدماتها، ومع تعزيز الاستفادة من البيانات والأنظمة لدعم أعمال الهيئة 6. تنظيم الاستفادة من البنية التحتية التقنية بما يضمن استمرارية الأعمال وحوكمة الكفاءة التشغيلية | E4: ◂ 3. مبادرة تعزيز كفاءة واستدامة البنية التحتية التقنية | F4: GAP-T-11، GAP-T-12 | G4: AR07، BR10، TR03 | H4: لايوجد نطاق او وصف | I4: استمرارية دعم الأنظمة الحيوية • الحفاظ على الأمان والتحديثات • الامتثال للمتطلبات التعاقدية | J4: • توريد وتركيب وترقية أجهزة موزع الأحمال والرخص الخاصة بها | K4: — | L4: — | M4: التقنية | N4: رأسمالي | O4: متوسطة | P4: 24/7/2023 | Q4: 24/7/2026 | R4: قائم | S4: 0 | T4: 10297790
A5: 4 | B5: تقديم الخدمات الاستشارية لقطاع البيانات والتحول الرقمي | C5: 1. دعم اتخاذ القرارات 2. تعزيز الكفاءة التشغيلية وكفاءة الإنفاق 3. تمكين التحول الرقمي | D5: 1. الامتثال للسياسات ذات العلاقة بمجال البيانات والتحول الرقمي الناشئ من أنظمة الهيئة وخدماتها، ومع تعزيز الاستفادة من البيانات والأنظمة لدعم أعمال الهيئة 3. تعزيز الابتكار الرقمي المؤسسي من خلال استثمار التقنيات الناشئة والتحليلات المتقدمة والذكاء الاصطناعي لتطوير حلول رقمية فعّالة لدعم جودة التقويم والتعليم والتدريب، وتسهم في تحسين الكفاءة التشغيلية وتجربة المستفيد 4. بناء قدرات رقمية وطنية وتمكين الكفاءات المتخصصة والعامة في مجال البيانات والتحول الرقمي، من خلال مسارات تدريبية مستهدفة متوافقة مع معايير بناء الكفاءات | E5: تنفيذ خطة التحول الرقمية وتطبيقها ◂ 3. مبادرة تعزيز كفاءة واستدامة البنية التحتية التقنية | F5: GAP-B-14، GAP-B-28، GAP-T-15، GAP-T-19 | G5: AR05، AR08، BR06 | H5: تقديم الاستشارات و تقييم الوضع الراهن لقطاع البيانات و التحول الرقمي وإعداد الهيكلة التنظيمية و السياسات وتقديم التوصيات للتحديات التي تواجه القطاع بهدف تحسين أداءه والامتثال للأنظمة الحكومية والتعاميم والقرارات ذات العلاقة الخاصة بالتحول الرقمي وذلك وفق أفضل الممارسات. — استضافة مركز البيانات هيئة تقويم التعليم والتدريب من مقدم خدمة لعدم جاهزية الموقع الحالي | I5: تحسين كفاءة قطاع البيانات والتحول الرقمي. تعزيز الامتثال للأنظمة الحكومية والتعاميم. معالجة التحديات التنظيمية والتقنية. دعم اتخاذ القرار عبر استشارات متخصصة. رفع جاهزية القطاع للتحول الرقمي المستدام. | J5: — | K5: قطاع البيانات والتحول الرقمي | L5: — | M5: كل المجالات | N5: تشغيلي | O5: متوسطة | P5: 46026 | Q5: 47122 | R5: قائم | S5: 0 | T5: 22668179
A6: 5 | B6: مشروع البنية التحتية لنظام سطح المكتب الافتراضي | C6: 2. تعزيز الكفاءة التشغيلية وكفاءة الإنفاق 3. تمكين التحول الرقمي | D6: 5. تحقيق التميز في تقديم الخدمات الرقمية من خلال التوسع في رقمنة الخدمات، وتحسين تجربة المستفيدين بما يضمن الامتثال لمعايير الحكومة الرقمية 6. تنظيم الاستفادة من البنية التحتية التقنية بما يضمن استمرارية الأعمال وحوكمة الكفاءة التشغيلية | E6: رفع جاهزية واستدامة البنية التحتية التقنية ◂ 3. مبادرة تعزيز كفاءة واستدامة البنية التحتية التقنية | F6: GAP-T-10، GAP-T-11 | G6: AR07، AR15، AR16، AR20، BR17، BR20، TR03 | H6: توريد وتطوير الأنظمة الافتراضية لسطح المكتب VDI وذلك لتسهيل عمليةدخول الموظفين على اجهزتهم الافتراضية عن بعد. | I6: دعم مرنة بيئات العمل عن بعد . تسهيل إدارة الموارد التقنية. تقليل الأعطال المرتبطة بالأجهزة المحلية. تعزيز الأمان والتحكم المركزي. | J6: • مشروع البنية التحتية لنظام سطح المكتب الافتراضي(تجديد العقد) | K6: قطاع البيانات والتحول الرقمي | L6: الشركة العربية لخدمات الانترنت و الاتصالات | M6: التقنية | N6: تشغيلي | O6: متوسطة | P6: 45420 | Q6: 13/6/2027 | R6: قائم | S6: 80 | T6: 8126289.8
A7: 6 | B7: الدعم الفني لأنظمة إدارة الموارد ساب | C7: 2. تعزيز الكفاءة التشغيلية وكفاءة الإنفاق | D7: 1. الامتثال للسياسات ذات العلاقة بمجال البيانات والتحول الرقمي الناشئ من أنظمة الهيئة وخدماتها، ومع تعزيز الاستفادة من البيانات والأنظمة لدعم أعمال الهيئة 6. تنظيم الاستفادة من البنية التحتية التقنية بما يضمن استمرارية الأعمال وحوكمة الكفاءة التشغيلية | E7: ◂ 4. مبادرة تطوير الحلول والخدمات الرقمية | F7: GAP-A-05، GAP-T-12، GAP-T-14 | G7: AR07، BR10، BR17، BR20، TR03 | H7: تجديد رخص وترقية و تحديث أنظمة الموارد المالية و البشرية | I7: دعم التحول الرقمي للهيئة • تعزيز الكفاءة التشغيلية • تحسين جودة الخدمات | J7: • مشروع الصيانة والدعم الفني لأجهزة البصمة في هيئة تقويم التعليم والتدريب و المراكز التابعة لها | K7: — | L7: — | M7: التقنية | N7: تشغيلي | O7: متوسطة | P7: 14/07/2025 | Q7: 14/07/2027 | R7: قائم | T7: 4483249.7
A8: 7 | B8: تجديد رخص أنظمة | C8: 2. تعزيز الكفاءة التشغيلية وكفاءة الإنفاق 6. المواءمة الاستراتيجية | D8: 1. الامتثال للسياسات ذات العلاقة بمجال البيانات والتحول الرقمي الناشئ من أنظمة الهيئة وخدماتها، ومع تعزيز الاستفادة من البيانات والأنظمة لدعم أعمال الهيئة 6. تنظيم الاستفادة من البنية التحتية التقنية بما يضمن استمرارية الأعمال وحوكمة الكفاءة التشغيلية | E8: ترشيد الإنفاق التقني وإدارة الرخص بفعالية ◂ 2. مبادرة الجاهزية التشغيلية واستمرارية الأعمال | F8: GAP-B-01، GAP-D-03، GAP-D-11، GAP-D-12، GAP-T-12 | G8: AR07، AR10، BR10، BR15، TR03 | H8: تجديد رخصة أنظمة إدارة الموارد ال مؤسسية (SAP S4Hana + SuccessFactors) ERP والتي تسعى من خلالها الهيئة إلى استمرارية الاعمال في الأنظمة المالية والموارد البشرية. | I8: استمرارية الاعمال في الأنظمة المالية والموارد البشرية. | J8: • تجديد رخص أنظمة (SAP) | K8: الإدارة العامة لتقنية المعلومات | L8: شركة أدوات وحلول | M8: التقنية | N8: تشغيلي | O8: متوسطة | P8: 45631 | Q8: 46726 | R8: قائم | S8: 0 | T8: 5651033.8
A9: 8 | B9: الربط الشبكي لمقرات الاختبارات المحوسبة | C9: 4. دعم تحسين تجربة المستفيد 6. المواءمة الاستراتيجية | D9: 2. تمكين التكامل التقني مع الجهات الحكومية ذات العلاقة عبر قنوات البيانات الوطنية، لتبادل البيانات وتقديم خدمات موحدة ومترابطة للمستفيدين 4. بناء قدرات رقمية وطنية وتمكين الكفاءات المتخصصة والعامة في مجال البيانات والتحول الرقمي، من خلال مسارات تدريبية مستهدفة متوافقة مع معايير بناء الكفاءات 5. تحقيق التميز في تقديم الخدمات الرقمية من خلال التوسع في رقمنة الخدمات، وتحسين تجربة المستفيدين بما يضمن الامتثال لمعايير الحكومة الرقمية | E9: ◂ 3. مبادرة تعزيز كفاءة واستدامة البنية التحتية التقنية | F9: GAP-B-01، GAP-B-05، GAP-B-14، GAP-B-20، GAP-B-21، GAP-B-22، GAP-B-24، GAP-B-25، GAP-B-28 | G9: AR09، BR04، BR06 | H9: تقديم خدمة الربط الشبكي 5G في هيئة تقويم التعليم والتدريب لجميع مقرات الاختبارات | I9: دعم منظومة الاختبارات والتقويم • رفع جودة إجراء الاختبارات الرقمية | J9: • تقديم خدمات لأنظمة تطبيق الاختبارات المحوسبة • التجهيز والتشغيل التقني لمقرات الاختبارات المحوسبة • التجهيز والتشغيل التقني لمقرات الاختبارات المحوسبة بجميع مناطق المملكة | K9: — | L9: — | M9: الأعمال | N9: تشغيلي | O9: منخفضة | P9: 46478 | Q9: 47574 | R9: لم يبدأ | S9: 0 | T9: 2305980
A10: 9 | B10: تأمين خدمة التحقق من بيانات المتقدمين يقين | C10: 1. دعم اتخاذ القرارات 4. دعم تحسين تجربة المستفيد 5. تعزيز الحوكمة المؤسسية | D10: 1. الامتثال للسياسات ذات العلاقة بمجال البيانات والتحول الرقمي الناشئ من أنظمة الهيئة وخدماتها، ومع تعزيز الاستفادة من البيانات والأنظمة لدعم أعمال الهيئة 2. تمكين التكامل التقني مع الجهات الحكومية ذات العلاقة عبر قنوات البيانات الوطنية، لتبادل البيانات وتقديم خدمات موحدة ومترابطة للمستفيدين 5. تحقيق التميز في تقديم الخدمات الرقمية من خلال التوسع في رقمنة الخدمات، وتحسين تجربة المستفيدين بما يضمن الامتثال لمعايير الحكومة الرقمية | E10: تحسين جودة وتكامل البيانات وفق المعايير الوطنية ◂ 5. مبادرة تحسين تجربة المستفيد الرقمية | F10: GAP-A-01، GAP-A-07، GAP-A-09، GAP-B-01، GAP-B-03، GAP-B-05، GAP-B-12، GAP-B-20، GAP-B-21، GAP-B-22، GAP-B-24، GAP-B-25 | G10: AR18، BR03، TR01 | H10: خدمة التحقق من بيانات المتقدمين لاختبارات الهيئة في مركز المعلومات الوطني والهدف من هذه الخدمة هو تسهيل مهمة التأكد من بيانات المتقدمين لاختبارات الهيئة لتلافي الأخطاء في الادخال والتحقق من صحة البيانات. | I10: تسريع عملية التحقق من الهوية. تقليل الأخطاء اليدوية في البيانات. تعزيز الأمان والثقة في البيانات. التكامل مع الأنظمة الوطنية للتحقق الفوري. | J10: • تأمين خدمة التحقق من بيانات المتقدمين يقين(تجديد العقد) | K10: قطاع البيانات والتحول الرقمي | L10: شركة عِلم | M10: الأعمال | N10: تشغيلي | O10: متوسطة | P10: 46753 | Q10: 47119 | R10: لم يبدأ | S10: 100 | T10: 11488500
A11: 10 | B11: تأمين خدمة الرسائل النصية لهيئة تقويم التعليم والتدريب (تجديد العقد) | C11: 2. تعزيز الكفاءة التشغيلية وكفاءة الإنفاق 3. تمكين التحول الرقمي 4. دعم تحسين تجربة المستفيد | D11: 2. تمكين التكامل التقني مع الجهات الحكومية ذات العلاقة عبر قنوات البيانات الوطنية، لتبادل البيانات وتقديم خدمات موحدة ومترابطة للمستفيدين 4. بناء قدرات رقمية وطنية وتمكين الكفاءات المتخصصة والعامة في مجال البيانات والتحول الرقمي، من خلال مسارات تدريبية مستهدفة متوافقة مع معايير بناء الكفاءات 5. تحقيق التميز في تقديم الخدمات الرقمية من خلال التوسع في رقمنة الخدمات، وتحسين تجربة المستفيدين بما يضمن الامتثال لمعايير الحكومة الرقمية | E11: ◂ 5. مبادرة تحسين تجربة المستفيد الرقمية | F11: GAP-A-06، GAP-B-05، GAP-B-14، GAP-B-28 | G11: AR07، AR15، BR06، TR03 | H11: تأمين خدمة الرسائل النصية ) SMS Gateway ( حزم الرسائل بحيث يوفر النظام مرونة عالية في الربط مع الأنظمة الداخلية للهيئة وكذلك توفير واجهات إدارة المستخدمين وشاشات خاصة لمراقبة حالة الرسائل وأعدادها. | I11: استمرارية دعم الأنظمة الحيوية • الحفاظ على الأمان والتحديثات • الامتثال للمتطلبات التعاقدية • تحسين تجربة المستفيد • تسهيل الوصول إلى الخدمات الرقمية | J11: • تأمين خدمة الرسائل النصية لهيئة تقويم التعليم والتدريب | K11: — | L11: — | M11: التطبيقات و التقنية و الأعمال | N11: تشغيلي | O11: عالية | P11: 18/4/2027 | Q11: 18/4/2030 | R11: لم يبدأ | S11: 0 | T11: 20000000
A12: 11 | B12: تشغيل وصيانة أنظمة هيئة تقويم التعليم والتدريب | C12: 2. تعزيز الكفاءة التشغيلية وكفاءة الإنفاق 4. دعم تحسين تجربة المستفيد 5. تعزيز الحوكمة المؤسسية | D12: 4. بناء قدرات رقمية وطنية وتمكين الكفاءات المتخصصة والعامة في مجال البيانات والتحول الرقمي، من خلال مسارات تدريبية مستهدفة متوافقة مع معايير بناء الكفاءات 5. تحقيق التميز في تقديم الخدمات الرقمية من خلال التوسع في رقمنة الخدمات، وتحسين تجربة المستفيدين بما يضمن الامتثال لمعايير الحكومة الرقمية 6. تنظيم الاستفادة من البنية التحتية التقنية بما يضمن استمرارية الأعمال وحوكمة الكفاءة التشغيلية | E12: ◂ 4. مبادرة تطوير الحلول والخدمات الرقمية | F12: GAP-A-06، GAP-B-04، GAP-B-09، GAP-B-14، GAP-B-15، GAP-B-16، GAP-B-17، GAP-B-28، GAP-D-03، GAP-D-11، GAP-D-12 | G12: BR06، TR03 | H12: توفير الأدوات التقنية اللازمة والكوادر المؤهلة فنياً لمراقبة جميع الأنشطة والعمليات التي تهدف الى ضمان استمرارية أداء خدمات المؤسسات التعليمية والتدريبية وعملها بشكل سلس وفعال وبكامل طاقتها وعلى النحو الأمثل بشكل مستمر دون توقف 24/7 وتقليل حدوث الأخطاء والمشاكل الفنية وأخذ التدابير الاستباقية والاستجابة الكاملة لمتطلبات التغيير لضمان تحسين ورفع جودتها وتلبية متطلبات العمل وتحسين تجربة المستخدم.. | I12: ضمان استمرارية الخدمات التقنية • تقليل الأعطال والانقطاعات • بناء القدرات الرقمية للموظفين • تعزيز ثقافة التعلم المؤسسي | J12: • تأمين خدمة الرسائل النصية لهيئة تقويم التعليم والتدريب (تجديد العقد) • مشروع الصيانة والدعم الفني لأجهزة البصمة في هيئة تقويم التعليم والتدريب و المراكز التابعة لها • تأسيس وتنفيذ وتشغيل البنية المؤسسية في هيئة تقويم التعليم و التدريب | K12: — | L12: — | M12: التقنية و الأعمال | N12: تشغيلي | O12: عالية | P12: 47209 | Q12: 47939 | R12: لم يبدأ | S12: 0 | T12: 120000000
A13: 12 | B13: تطوير نظامي إدارة استكشاف الأصول التقنية والأجهزة الطرفية | C13: 2. تعزيز الكفاءة التشغيلية وكفاءة الإنفاق 3. تمكين التحول الرقمي 5. تعزيز الحوكمة المؤسسية | D13: 1. الامتثال للسياسات ذات العلاقة بمجال البيانات والتحول الرقمي الناشئ من أنظمة الهيئة وخدماتها، ومع تعزيز الاستفادة من البيانات والأنظمة لدعم أعمال الهيئة 5. تحقيق التميز في تقديم الخدمات الرقمية من خلال التوسع في رقمنة الخدمات، وتحسين تجربة المستفيدين بما يضمن الامتثال لمعايير الحكومة الرقمية 6. تنظيم الاستفادة من البنية التحتية التقنية بما يضمن استمرارية الأعمال وحوكمة الكفاءة التشغيلية | E13: ◂ 3. مبادرة تعزيز كفاءة واستدامة البنية التحتية التقنية | F13: GAP-A-01، GAP-A-09، GAP-B-01، GAP-B-05، GAP-B-20، GAP-B-21، GAP-B-22، GAP-B-24، GAP-B-25، GAP-T-11، GAP-T-12 | G13: AR07، AR18 | H13: يشمل نطاق العمل تقديم خدمات التشغيل والدعم الفني والصيانة لكلٍ من نظام إدارة الخدمات ونظام إدارة الأصول التقنية، بالإضافة إلى توريد رخص استكشاف الأصول وإدارة الثغرات والتحديثات الأمنية ونظام إدارة الأجهزة الطرفية، مع تطبيق آلية فعّالة لإدارة التصحيحات الأمنية، بما يعزز التحكم في الأصول الرقمية ويرفع مستوى الأمان والامتثال والتكامل مع أنظمة الهيئة | I13: دعم التحول الرقمي للهيئة • تعزيز الكفاءة التشغيلية • تحسين جودة الخدمات | J13: — | K13: — | L13: — | M13: التطبيقات و التقنية و الأمن السيبراني | N13: تشغيلي | O13: متوسطة | P13: 46753 | Q13: 47849 | R13: لم يبدأ | S13: 0 | T13: 6500000
A14: 13 | B14: تقديم خدمة أداء الاختبارات الرقمية بالرياض ، الدمام ، المدينة المنورة ، الطائف ، بريدة ، الهفوف ،جازان ، جدة | C14: 2. تعزيز الكفاءة التشغيلية وكفاءة الإنفاق 4. دعم تحسين تجربة المستفيد 5. تعزيز الحوكمة المؤسسية | D14: 3. تعزيز الابتكار الرقمي المؤسسي من خلال استثمار التقنيات الناشئة والتحليلات المتقدمة والذكاء الاصطناعي لتطوير حلول رقمية فعّالة لدعم جودة التقويم والتعليم والتدريب، وتسهم في تحسين الكفاءة التشغيلية وتجربة المستفيد 5. تحقيق التميز في تقديم الخدمات الرقمية من خلال التوسع في رقمنة الخدمات، وتحسين تجربة المستفيدين بما يضمن الامتثال لمعايير الحكومة الرقمية 6. تنظيم الاستفادة من البنية التحتية التقنية بما يضمن استمرارية الأعمال وحوكمة الكفاءة التشغيلية | E14: تحسين تجربة المستفيد وتوحيد مسار ات تقديم الخدمات الرقمية ◂ 5. مبادرة تحسين تجربة المستفيد الرقمية | F14: GAP-A-02، GAP-A-03، GAP-A-06، GAP-A-08، GAP-B-01، GAP-B-04، GAP-B-08، GAP-B-09، GAP-B-15، GAP-B-16، GAP-B-17، GAP-B-20، GAP-B-21، GAP-B-22، GAP-B-24، GAP-B-25، GAP-D-03، GAP-D-11، GAP-D-12 | G14: AR09، BR18، TR03 | H14: تقديم خدمة أداء الاختبارات الرقمية بداية من استقبال المختبرين وتوثيق بياناتهم وتنظيم دخولهم لقاعة الاختبار ومراقبة الاختبارات إلى انتهائها وتنظيم مغادرتهم. | I14: توسيع الوصول الجغرافي للمتقدمين من خلال توفير نقاط اختبار في مختلف المناطق. تحسين تجربة المستفيد عبر تقنيات اختبار رقمية مريحة وسهلة الاستخدام. رفع كفاءة العمليات من خلال تقليل الاعتماد على الاختبارات الورقية. ضمان استمرارية الخدمة من خلال بنية تحتية موزعة تخفف من مخاطر التوقف المحلي. | J14: — | K14: مركز قياس | L14: — | M14: الأعمال | N14: تشغيلي | O14: متوسطة | P14: 45787 | Q14: 47613 | R14: قائم | S14: 0 | T14: 3.7611758e+08
A15: 14 | B15: توفير وتركيب أداة التطوير منخفضة صفرية الترميز (تجديد العقد) | C15: 2. تعزيز الكفاءة التشغيلية وكفاءة الإنفاق 3. تمكين التحول الرقمي 4. دعم تحسين تجربة المستفيد | D15: 5. تحقيق التميز في تقديم الخدمات الرقمية من خلال التوسع في رقمنة الخدمات، وتحسين تجربة المستفيدين بما يضمن الامتثال لمعايير الحكومة الرقمية 6. تنظيم الاستفادة من البنية التحتية التقنية بما يضمن استمرارية الأعمال وحوكمة الكفاءة التشغيلية | E15: ◂ 4. مبادرة تطوير الحلول والخدمات الرقمية | F15: GAP-B-01، GAP-B-04، GAP-B-09، GAP-B-15، GAP-B-16، GAP-B-17، GAP-B-20، GAP-B-21، GAP-B-22، GAP-B-24، GAP-B-25 | G15: AR07، BR02، TR03 | H15: الاستفادة من أدوات التطوير منخفضة/صفرية الترميز Low/No Code Development Tool لتلبية احتياجات الهيئة في عمليات التحول الرقمي وذلك من خلال توفير المنتجات الرقمية بطريقة سريعة وفعالة والتي تقود إلى تسريع عمليات التحول الرقمي وزيادة الكفاءة التشغيلية ورقمنه الأعمال وتحسين تجربة المستخدم. | I15: استمرارية دعم الأنظمة الحيوية • الحفاظ على الأمان والتحديثات • الامتثال للمتطلبات التعاقدية | J15: • توفير وتركيب أداة التطوير منخفضة صفرية الترميز | K15: — | L15: — | M15: التطبيقات و التقنية | N15: تشغيلي | O15: متوسطة | P15: 17/12/2027 | Q15: 47574 | R15: لم يبدأ | S15: 0 | T15: 3982680
A16: 15 | B16: توفير وتركيب أداة التطوير منخفضة صفرية الترميز | C16: 2. تعزيز الكفاءة التشغيلية وكفاءة الإنفاق 3. تمكين التحول الرقمي 4. دعم تحسين تجربة المستفيد | D16: 5. تحقيق التميز في تقديم الخدمات الرقمية من خلال التوسع في رقمنة الخدمات، وتحسين تجربة المستفيدين بما يضمن الامتثال لمعايير الحكومة الرقمية | E16: ◂ 4. مبادرة تطوير الحلول والخدمات الرقمية | F16: GAP-B-01، GAP-B-04، GAP-B-09، GAP-B-15، GAP-B-16، GAP-B-17، GAP-B-20، GAP-B-21، GAP-B-22، GAP-B-24، GAP-B-25 | G16: AR18، BR01، BR02 | H16: الاستفادة من أدوات التطوير منخفضة/صفرية الترميز Low/No Code Development Tool لتلبية احتياجات الهيئة في عمليات التحول الرقمي وذلك من خلال توفير المنتجات الرقمية بطريقة سريعة وفعالة والتي تقود إلى تسريع عمليات التحول الرقمي وزيادة الكفاءة التشغيلية ورقمنه الأعمال وتحسين تجربة المستخدم. | I16: دعم التحول الرقمي للهيئة • تعزيز الكفاءة التشغيلية • تحسين جودة الخدمات | J16: • توفير وتركيب أداة التطوير منخفضة صفرية الترميز (تجديد العقد) | K16: — | L16: — | M16: التطبيقات | N16: تشغيلي | O16: متوسطة | P16: 16/12/2024 | Q16: 16/12/2027 | R16: قائم | T16: 3982680
A17: 16 | B17: تشغيل وصيانة تطبيق ألف ياء لاختبارات بطارية الذكاء المرتبطة بقياس القدرات العقلية | C17: 2. تعزيز الكفاءة التشغيلية وكفاءة الإنفاق 3. تمكين التحول الرقمي 4. دعم تحسين تجربة المستفيد | D17: 3. تعزيز الابتكار الرقمي المؤسسي من خلال استثمار التقنيات الناشئة والتحليلات المتقدمة والذكاء الاصطناعي لتطوير حلول رقمية فعّالة لدعم جودة التقويم والتعليم والتدريب، وتسهم في تحسين الكفاءة التشغيلية وتجربة المستفيد 5. تحقيق التميز في تقديم الخدمات الرقمية من خلال التوسع في رقمنة الخدمات، وتحسين تجربة المستفيدين بما يضمن الامتثال لمعايير الحكومة الرقمية 6. تنظيم الاستفادة من البنية التحتية التقنية بما يضمن استمرارية الأعمال وحوكمة الكفاءة التشغيلية | E17: تحسين تجربة المستفيد وتوحيد مسار ات تقديم الخدمات الرقمية ◂ 1. مبادرة الذكاء الاصطناعي والتحليلات المتقدمة | F17: GAP-B-01، GAP-B-17، GAP-B-20، GAP-B-21، GAP-B-22، GAP-B-24، GAP-B-25 | G17: AR07، BR07، TR03 | H17: إعادة ترتيب مكونات التطبيق التقنية بما قد يتطلب إعادة بناء الواجهة الخلفية بما يتلاءم مع التقنيات المستخدمة في بيئة الهيئة | I17: قياس قدرات الطلاب العقلية بطريقة علمية. تحسين أدوات التقويم والتشخيص. دعم التوجيه التربوي والأكاديمي. تعزيز الابتكار في تصميم الاختبارات. | J17: • تشغيل وصيانة تطبيق ألف ياء لاختبارات بطارية الذكاء المرتبطة بقياس القدرات العقلية ( تجديد عقد ) | K17: مركز قياس | L17: — | M17: التطبيقات | N17: تشغيلي | O17: متوسطة | P17: 23/04/2025 | Q17: 23/04/2028 | R17: قائم | S17: 0 | T17: 6000000
A18: 17 | B18: توفير أداة لإنشاء الاستبيانات والتقييم جاهزة للتطبيق | C18: 1. دعم اتخاذ القرارات 3. تمكين التحول الرقمي 6. المواءمة الاستراتيجية | D18: 3. تعزيز الابتكار الرقمي المؤسسي من خلال استثمار التقنيات الناشئة والتحليلات المتقدمة والذكاء الاصطناعي لتطوير حلول رقمية فعّالة لدعم جودة التقويم والتعليم والتدريب، وتسهم في تحسين الكفاءة التشغيلية وتجربة المستفيد 5. تحقيق التميز في تقديم الخدمات الرقمية من خلال التوسع في رقمنة الخدمات، وتحسين تجربة المستفيدين بما يضمن الامتثال لمعايير الحكومة الرقمية | E18: رفع كفاءة اتخاذ القرار المبني على البيانات ◂ 4. مبادرة تطوير الحلول والخدمات الرقمية | F18: GAP-B-01، GAP-B-17، GAP-B-18، GAP-B-20، GAP-B-21، GAP-B-22، GAP-B-24، GAP-B-25 | G18: AR18، BR01، BR02 | H18: أداة لانشاء الاستبانات بشكل فورية وإمكانية تصديرها كتقارير أو بيانات | I18: تسهيل جمع البيانات وتحليلها. دعم قرارات مبنية على نتائج دقيقة. توحيد آليات التقييم في الهيئة. تقليل الاعتماد على النماذج الورقية. | J18: • تركيب وتشغيل اداة تحليل البيانات وتعلم الآلة جاهزة للتطبيق | K18: قطاع البيانات والتحول الرقمي | L18: ليدرز سوفت لتقنية المعلومات | M18: الأعمال و التطبيقات والبيانات | N18: تشغيلي | O18: منخفضة | P18: 44984 | Q18: 46080 | R18: منتهي | S18: 100 | T18: 443599
A19: 18 | B19: مشروع الصيانة والدعم الفني لأجهزة البصمة في هيئة تقويم التعليم والتدريب و المراكز التابعة لها | C19: 2. تعزيز الكفاءة التشغيلية وكفاءة الإنفاق | D19: 4. بناء قدرات رقمية وطنية وتمكين الكفاءات المتخصصة والعامة في مجال البيانات والتحول الرقمي، من خلال مسارات تدريبية مستهدفة متوافقة مع معايير بناء الكفاءات 6. تنظيم الاستفادة من البنية التحتية التقنية بما يضمن استمرارية الأعمال وحوكمة الكفاءة التشغيلية | E19: ◂ 3. مبادرة تعزيز كفاءة واستدامة البنية التحتية التقنية | F19: GAP-B-14، GAP-B-28، GAP-T-11 | G19: AR07، BR06، TR03 | H19: لايوجد نطاق او وصف | I19: ضمان استمرارية الخدمات التقنية • تقليل الأعطال والانقطاعات • بناء القدرات الرقمية للموظفين • تعزيز ثقافة التعلم المؤسسي | J19: — | K19: — | L19: — | M19: التقنية و الأعمال | N19: تشغيلي | O19: منخفضة | P19: 45539 | Q19: 46634 | R19: قائم | S19: 0 | T19: 726701.1
A20: 19 | B20: تأسيس وتنفيذ وتشغيل البنية المؤسسية في هيئة تقويم التعليم و التدريب | C20: 3. تمكين التحول الرقمي 5. تعزيز الحوكمة المؤسسية 6. المواءمة الاستراتيجية | D20: 1. الامتثال للسياسات ذات العلاقة بمجال البيانات والتحول الرقمي الناشئ من أنظمة الهيئة وخدماتها، ومع تعزيز الاستفادة من البيانات والأنظمة لدعم أعمال الهيئة 2. تمكين التكامل التقني مع الجهات الحكومية ذات العلاقة عبر قنوات البيانات الوطنية، لتبادل البيانات وتقديم خدمات موحدة ومترابطة للمستفيدين 3. تعزيز الابتكار الرقمي المؤسسي من خلال استثمار التقنيات الناشئة والتحليلات المتقدمة والذكاء الاصطناعي لتطوير حلول رقمية فعّالة لدعم جودة التقويم والتعليم والتدريب، وتسهم في تحسين الكفاءة التشغيلية وتجربة المستفيد | E20: إعداد خطة تحول رقمية ◂ 6. مبادرة التمكين الرقمي | F20: GAP-A-01، GAP-A-09، GAP-B-01، GAP-B-02، GAP-B-05، GAP-B-06، GAP-B-10، GAP-B-13، GAP-B-14، GAP-B-20، GAP-B-21، GAP-B-22، GAP-B-24، GAP-B-25، GAP-B-28، GAP-B-30 | G20: AR07، BR01، BR02، BR06، DR01 | H20: تأسيس وتنفيذ وتشغيل البنية المؤسسية في هيئة تقويم التعليم والتدريب باستخدام إطار العمل العاملي "TOGAF"، بحيث يؤدي اعتمادها إلى الموائمة بين الأعمال وتقنية المعلومات، وزيادة إمكانية التشغيل البيني، وتحسين جودة إجراءات العمل و إدارة الأصول، والتكامل بين التطبيقات، وخفض المخاطر وانخفاض التكاليف، وكذلك ضمان تحقيق الموائمة مع المبادرات الوطنية التقنية و وضع المعايير والأدلة الاسترشادية للخدمات والتطبيقات والبيانات والتقنية. | I20: مواءمة الأهداف التقنية مع الاستراتيجية المؤسسية. توحيد المعايير والمنهجيات المؤسسية. تعزيز حوكمة القرار التقني. دعم التخطيط والتحول الرقمي. | J20: • تأمين خدمة الرسائل النصية لهيئة تقويم التعليم والتدريب (تجديد العقد) • تشغيل وصيانة أنظمة هيئة تقويم التعليم والتدريب • مشروع الصيانة والدعم الفني لأجهزة البصمة في هيئة تقويم التعليم والتدريب و المراكز التابعة لها | K20: قطاع البيانات والتحول الرقمي | L20: شركة ريناد المجد | M20: كل المجالات | N20: تشغيلي | O20: متوسطة | P20: 45298 | Q20: 46394 | R20: قائم | S20: 0 | T20: 3439000
A21: 20 | B21: تركيب وتشغيل اداة المحاكاة الإفتراضية للبيانات | C21: 1. دعم اتخاذ القرارات 2. تعزيز الكفاءة التشغيلية وكفاءة الإنفاق 3. تمكين التحول الرقمي | D21: 3. تعزيز الابتكار الرقمي المؤسسي من خلال استثمار التقنيات الناشئة والتحليلات المتقدمة والذكاء الاصطناعي لتطوير حلول رقمية فعّالة لدعم جودة التقويم والتعليم والتدريب، وتسهم في تحسين الكفاءة التشغيلية وتجربة المستفيد 5. تحقيق التميز في تقديم الخدمات الرقمية من خلال التوسع في رقمنة الخدمات، وتحسين تجربة المستفيدين بما يضمن الامتثال لمعايير الحكومة الرقمية | E21: تحسين جودة وتكامل البيانات وفق المعايير الوطنية ◂ 1. مبادرة الذكاء الاصطناعي والتحليلات المتقدمة | F21: GAP-B-11، GAP-B-12، GAP-D-05، GAP-D-07، GAP-D-17، GAP-D-20، GAP-D-23 | G21: AR05، AR08، BR18 | H21: تركيب حلول المحاكاة الافتراضية للبيانات (Data virtualization tool) وتشغيلها. | I21: دعم اختبار السيناريوهات وتحليل البيانات. تحسين دقة التقارير دون المساس بالبيانات الفعلية. تقليل المخاطر المرتبطة بالبيانات الحقيقية. | J21: • تركيب وتشغيل اداة تحليل البيانات وتعلم الآلة جاهزة للتطبيق | K21: قطاع البيانات والتحول الرقمي | L21: شركة الإجادة للنظم المحدودة | M21: البيانات | N21: تشغيلي | O21: متوسطة | P21: 24/03/2024 | Q21: 26/03/2026 | R21: منتهي | S21: 100 | T21: 3898500
A22: 21 | B22: توفير خدمة للتعلم الإلكتروني جاهزة للاستخدام | C22: 4. دعم تحسين تجربة المستفيد | D22: 5. تحقيق التميز في تقديم الخدمات الرقمية من خلال التوسع في رقمنة الخدمات، وتحسين تجربة المستفيدين بما يضمن الامتثال لمعايير الحكومة الرقمية | E22: تحسين تجربة المستفيد وتوحيد مسار ات تقديم الخدمات الرقمية ◂ 4. مبادرة تطوير الحلول والخدمات الرقمية | F22: GAP-B-14، GAP-B-18، GAP-B-28 | G22: AR09، BR02، BR04 | H22: توفير خدمة للتعلم الإلكتروني جاهزة للاستخدام | I22: توفير خدمات للتعليم الالكتروني | J22: • توفير خدمة للتعلم الإلكتروني جاهزة للاستخدام(تجديد العقد) | K22: الإدارة العامة للتطوير | L22: شركة نسيج للتقنية | M22: الأعمال | N22: تشغيلي | O22: متوسطة | P22: 45300 | Q22: 46396 | R22: قائم | S22: 0 | T22: 538430
A23: 22 | B23: مشروع شراء وتجديد رخص البرامج في هيئة تقويم التعليم والتدريب | C23: 2. تعزيز الكفاءة التشغيلية وكفاءة الإنفاق | D23: 1. الامتثال للسياسات ذات العلاقة بمجال البيانات والتحول الرقمي الناشئ من أنظمة الهيئة وخدماتها، ومع تعزيز الاستفادة من البيانات والأنظمة لدعم أعمال الهيئة 4. بناء قدرات رقمية وطنية وتمكين الكفاءات المتخصصة والعامة في مجال البيانات والتحول الرقمي، من خلال مسارات تدريبية مستهدفة متوافقة مع معايير بناء الكفاءات 6. تنظيم الاستفادة من البنية التحتية التقنية بما يضمن استمرارية الأعمال وحوكمة الكفاءة التشغيلية | E23: ترشيد الإنفاق التقني وإدارة الرخص بفعالية ◂ 2. مبادرة الجاهزية التشغيلية واستمرارية الأعمال | F23: GAP-B-14، GAP-B-28، GAP-D-03، GAP-D-11، GAP-D-12، GAP-T-12 | G23: BR06، TR03 | H23: شراء وتجديد رخص البرامج التشغيلية و تجديد رخص سيسكو في هيئة تقويم التعليم والتدريب — شراء وتجديد رخص البرامج التشغيلية تقويم التعليم والتدريب | I23: إستمرارية الأعمال لتشغيل برامج الهيئة | J23: • تأمين خدمة الرسائل النصية لهيئة تقويم التعليم والتدريب (تجديد العقد) • تشغيل وصيانة أنظمة هيئة تقويم التعليم والتدريب • مشروع الصيانة والدعم الفني لأجهزة البصمة في هيئة تقويم التعليم والتدريب و المراكز التابعة لها | K23: الإدارة العامة لتقنية المعلومات | L23: — | M23: التقنية | N23: رأسمالي | O23: متوسطة | P23: 46478 | Q23: 47574 | R23: لم يبدأ | S23: 0 | T23: 50000000
A24: 23 | B24: صيانة وتطوير تطبيق التحقق من هوية المختبرين | C24: 2. تعزيز الكفاءة التشغيلية وكفاءة الإنفاق 3. تمكين التحول الرقمي 4. دعم تحسين تجربة المستفيد | D24: 1. الامتثال للسياسات ذات العلاقة بمجال البيانات والتحول الرقمي الناشئ من أنظمة الهيئة وخدماتها، ومع تعزيز الاستفادة من البيانات والأنظمة لدعم أعمال الهيئة 5. تحقيق التميز في تقديم الخدمات الرقمية من خلال التوسع في رقمنة الخدمات، وتحسين تجربة المستفيدين بما يضمن الامتثال لمعايير الحكومة الرقمية 6. تنظيم الاستفادة من البنية التحتية التقنية بما يضمن استمرارية الأعمال وحوكمة الكفاءة التشغيلية | E24: تحسين تجربة المستفيد وتوحيد مسار ات تقديم الخدمات الرقمية ◂ 5. مبادرة تحسين تجربة المستفيد الرقمية | F24: GAP-A-07، GAP-B-01، GAP-B-04، GAP-B-09، GAP-B-15، GAP-B-16، GAP-B-17، GAP-B-20، GAP-B-21، GAP-B-22، GAP-B-24، GAP-B-25، GAP-T-11 | G24: AR07، TR01، TR03 | H24: الصيانة والتطوير لنظام التحقق من هوية المختبرين من خلال الخصائص الحيوية (البصمة) وتأمين علميات تحقق من الهوية من مركز المعلومات الوطني عن طريق أجهزة قراءة البصمة بالاعتماد على البصمات المسجلة في قاعدة مركز المعلومات الوطني بغرض التحقق من هوية المختبر قبل الدخول لمقرات الاختبارات المحوسبة | I24: تعزيز أمن وموثوقية الاختبارات. تقليل فرص التزوير والانتحال. تحسين تجربة المستخدم في التحقق. | J24: • صيانة وتطوير تطبيق التحقق من هوية المختبرين(تجديد العقد) | K24: قطاع البيانات والتحول الرقمي | L24: المعالم الدولية لتقنية المعلومات | M24: الأعمال | N24: تشغيلي | O24: عالية | P24: 45720 | Q24: 46816 | R24: قائم | S24: 20 | T24: 40000000
A25: 24 | B25: تقديم خدمات لأنظمة تطبيق الاختبارات المحوسبة | C25: 3. تمكين التحول الرقمي 4. دعم تحسين تجربة المستفيد | D25: 5. تحقيق التميز في تقديم الخدمات الرقمية من خلال التوسع في رقمنة الخدمات، وتحسين تجربة المستفيدين بما يضمن الامتثال لمعايير الحكومة الرقمية | E25: ◂ 4. مبادرة تطوير الحلول والخدمات الرقمية | F25: GAP-B-01، GAP-B-20، GAP-B-21، GAP-B-22، GAP-B-24، GAP-B-25 | G25: AR18، BR01، BR02 | H25: تقديم خدمات لانظمة الاختبارات الرقمية والأنظمة الداعمة لها | I25: تحسين تجربة المستفيد • تسهيل الوصول إلى الخدمات الرقمية • دعم منظومة الاختبارات والتقويم • رفع جودة إجراء الاختبارات الرقمية | J25: • تقديم خدمات لأنظمة تطبيق الاختبارات المحوسبة | K25: — | L25: — | M25: التطبيقات | N25: تشغيلي | O25: عالية | P25: 46388 | Q25: — | R25: تجديد عقد | T25: 20000000
A26: 25 | B26: تشغيل وصيانة خدمات الافراد في هيئة تقويم التعليم والتدريب. | C26: 2. تعزيز الكفاءة التشغيلية وكفاءة الإنفاق 3. تمكين التحول الرقمي 4. دعم تحسين تجربة المستفيد | D26: 4. بناء قدرات رقمية وطنية وتمكين الكفاءات المتخصصة والعامة في مجال البيانات والتحول الرقمي، من خلال مسارات تدريبية مستهدفة متوافقة مع معايير بناء الكفاءات 5. تحقيق التميز في تقديم الخدمات الرقمية من خلال التوسع في رقمنة الخدمات، وتحسين تجربة المستفيدين بما يضمن الامتثال لمعايير الحكومة الرقمية 6. تنظيم الاستفادة من البنية التحتية التقنية بما يضمن استمرارية الأعمال وحوكمة الكفاءة التشغيلية | E26: رفع جاهزية واستدامة البنية التحتية التقنية ◂ 4. مبادرة تطوير الحلول والخدمات الرقمية | F26: GAP-A-06، GAP-B-01، GAP-B-04، GAP-B-09، GAP-B-14، GAP-B-15، GAP-B-16، GAP-B-17، GAP-B-28 | G26: AR06، BR04، BR06 | H26: توفير الأدوات التقنية اللازمة والكوادر المؤهلة فنياً لمراقبة جميع الأنشطة والعمليات المتضمنة في ضمان الأداء لخدمات الأفراد لتعمل بشكل سلس وفعال وبكامل طاقتها وعلى النحو الأمثل بشكل مستمر دون توقف 24/7 وتقليل حدوث الأخطاء والمشاكل الفنية وأخذ التدابير الاستباقية والاستجابة الكاملة لمتطلبات التغيير لضمان تحسين ورفع جودتها وتلبية متطلبات العمل وتحسين تجربة المستخدم.. | I26: تحسين تجربة المستخدم للأفراد. رفع موثوقية الخدمات المقدمة إلكترونيًا. تقليل الأعطال وتحسين استجابة الأنظمة. دعم الكفاءة التشغيلية الرقمية. | J26: • تشغيل وصيانة أنظمة هيئة تقويم التعليم والتدريب • تأسيس وتنفيذ وتشغيل البنية المؤسسية في هيئة تقويم التعليم و التدريب • تشغيل البنية المؤسسية في هيئة تقويم التعليم و التدريب | K26: الإدارة العامة للتطوير | L26: — | M26: الأعمال | N26: تشغيلي | O26: متوسطة | P26: 25/11/2025 | Q26: 25/11/2027 | R26: قائم | S26: 0 | T26: 19996367
A27: 26 | B27: منصة و تطبيق سديد | C27: 2. تعزيز الكفاءة التشغيلية وكفاءة الإنفاق 3. تمكين التحول الرقمي 4. دعم تحسين تجربة المستفيد | D27: 1. الامتثال للسياسات ذات العلاقة بمجال البيانات والتحول الرقمي الناشئ من أنظمة الهيئة وخدماتها، ومع تعزيز الاستفادة من البيانات والأنظمة لدعم أعمال الهيئة 5. تحقيق التميز في تقديم الخدمات الرقمية من خلال التوسع في رقمنة الخدمات، وتحسين تجربة المستفيدين بما يضمن الامتثال لمعايير الحكومة الرقمية 6. تنظيم الاستفادة من البنية التحتية التقنية بما يضمن استمرارية الأعمال وحوكمة الكفاءة التشغيلية | E27: ◂ 4. مبادرة تطوير الحلول والخدمات الرقمية | F27: GAP-B-01، GAP-B-04، GAP-B-09، GAP-B-15، GAP-B-16، GAP-B-17، GAP-B-20، GAP-B-21، GAP-B-22، GAP-B-24، GAP-B-25، GAP-T-12 | G27: AR06، AR14، BR02، BR04، BR16 | H27: منصة موحدة للخدمات المقدمة من قبل الهيئة للأفراد وتشمل على الاختبارات, الرخص, الدورات و ورش العمل. | I27: تحسين تجربة المستفيد • تسهيل الوصول إلى الخدمات الرقمية • أتمتة الإجراءات ورفع الكفاءة التشغيلية • تقليل الاعتماد على العمليات اليدوية | J27: • تطوير تطبيق ومنصة مستقبلهم • تطوير تطبيق ومنصة مستقبلهم | K27: — | L27: — | M27: التطبيقات و التقنية | N27: تشغيلي | O27: متوسطة | P27: 31/12/2024 | Q27: 31/12/2026 | R27: قائم
A28: 27 | B28: تطوير نظامي اختبارات الطوارئ والاختبارات المؤسسية | C28: 2. تعزيز الكفاءة التشغيلية وكفاءة الإنفاق 3. تمكين التحول الرقمي 4. دعم تحسين تجربة المستفيد | D28: 5. تحقيق التميز في تقديم الخدمات الرقمية من خلال التوسع في رقمنة الخدمات، وتحسين تجربة المستفيدين بما يضمن الامتثال لمعايير الحكومة الرقمية 6. تنظيم الاستفادة من البنية التحتية التقنية بما يضمن استمرارية الأعمال وحوكمة الكفاءة التشغيلية | E28: رفع الكفاءة التشغيلية من خلال الرقمنة ◂ 4. مبادرة تطوير الحلول والخدمات الرقمية | F28: GAP-B-01، GAP-B-20، GAP-B-21، GAP-B-22، GAP-B-24، GAP-B-25، GAP-D-03، GAP-D-11، GAP-D-12 | G28: AR13، AR18، BR02، TR03 | H28: تطوير نظامي اختبارات الطوارئ والاختبارات المؤسسية في المقرات الرقمية داخل الهيئة و خارجها و التأكد من عمليات تطبيق الاختبارات و تقديم الدعم الفني للحفاظ علي أداء عالٍ للنظام | I28: ضمان استمرارية التقييم في الظروف الاستثنائية. تنويع أساليب التقييم الرقمية. رفع مستوى الجاهزية المؤسسية. استجابة مرنة للأزمات. | J28: • تشغيل وصيانة اختبارات الطوارئ والاختبارات المؤسسية | K28: الإدارة العامة لأنظمة الاختبارات | L28: — | M28: التطبيقات و الأعمال | N28: تشغيلي | O28: متوسطة | P28: 45995 | Q28: 46360 | R28: قائم | S28: 0 | T28: 7912000
A29: 28 | B29: تطوير تطبيق ومنصة مستقبلهم | C29: 2. تعزيز الكفاءة التشغيلية وكفاءة الإنفاق 3. تمكين التحول الرقمي 4. دعم تحسين تجربة المستفيد | D29: 5. تحقيق التميز في تقديم الخدمات الرقمية من خلال التوسع في رقمنة الخدمات، وتحسين تجربة المستفيدين بما يضمن الامتثال لمعايير الحكومة الرقمية | E29: تحسين تجربة المستفيد وتوحيد مسار ات تقديم الخدمات الرقمية ◂ 4. مبادرة تطوير الحلول والخدمات الرقمية | F29: GAP-A-06، GAP-B-01، GAP-B-04، GAP-B-09، GAP-B-15، GAP-B-16، GAP-B-17، GAP-B-18، GAP-B-20، GAP-B-21، GAP-B-22، GAP-B-24، GAP-B-25 | G29: AR14، BR02، BR04 | H29: توفير الأدوات التقنية اللازمة والكوادر المؤهلة فنياً لمراقبة جميع الأنشطة والعمليات المتضمنة في ضمان الأداء لتطبيق مستقبلهم لتعمل بشكل سلس وفعال وبكامل طاقتها وعلى النحو الأمثل بشكل مستمر دون توقف 24/7 وتقليل حدوث الأخطاء والمشاكل الفنية وأخذ التدابير الاستباقية والاستجابة الكاملة لمتطلبات التغيير لضمان تحسين ورفع جودتها وتلبية متطلبات العمل وتحسين تجربة المستخدم.. | I29: رفع كفاءة التطبيق وتحسين أدائه. توفير دعم فني مستمر للمستخدمين. تقليل التوقفات الفنية والتقنية. تعزيز التفاعل مع أولياء الأمور. | J29: • صيانة وتطوير تطبيق التحقق من هوية المختبرين • صيانة وتطوير تطبيق التحقق من هوية المختبرين(تجديد العقد) • تطوير تطبيق ومنصة مستقبلهم | K29: إدارة التخطيط و الجودة | L29: — | M29: التطبيقات و الأعمال | N29: تشغيلي | O29: متوسطة | P29: 47027 | Q29: 47757 | R29: لم يبدأ | S29: 0 | T29: 24000000
A30: 29 | B30: توسيع نطاق تقديم الاختبارات الرقمية في مدن مختارة لتحسين الوصول الجغرافي (أبها , مكة المكرمة , حائل , الخرج, حفر الباطن ) | C30: 1. دعم اتخاذ القرارات 2. تعزيز الكفاءة التشغيلية وكفاءة الإنفاق 4. دعم تحسين تجربة المستفيد | D30: 3. تعزيز الابتكار الرقمي المؤسسي من خلال استثمار التقنيات الناشئة والتحليلات المتقدمة والذكاء الاصطناعي لتطوير حلول رقمية فعّالة لدعم جودة التقويم والتعليم والتدريب، وتسهم في تحسين الكفاءة التشغيلية وتجربة المستفيد 5. تحقيق التميز في تقديم الخدمات الرقمية من خلال التوسع في رقمنة الخدمات، وتحسين تجربة المستفيدين بما يضمن الامتثال لمعايير الحكومة الرقمية | E30: تحسين تجربة المستفيد وتوحيد مسار ات تقديم الخدمات الرقمية ◂ 5. مبادرة تحسين تجربة المستفيد الرقمية | F30: GAP-A-02، GAP-A-03، GAP-A-06، GAP-A-08، GAP-B-01، GAP-B-08، GAP-B-17، GAP-B-20، GAP-B-21، GAP-B-22، GAP-B-24، GAP-B-25 | G30: AR05، AR08، DR01 | H30: تقديم خدمة أداء الاختبارات الرقمية للجنسين بشكل منفصل في مدن أبها , مكة , حائل , الخرج, حفر الباطن ). بداية من استقبال المختبرين وتوثيق بياناتهم وتنظيم دخولهم لقاعة الاختبار ومراقبة الاختبارات إلى انتهائها وتنظيم مغادرتهم. | I30: تحسين إتاحة فرص التقييم. تقليل التكاليف المرتبطة بالتنقل. تعزيز التغطية الجغرافية للهيئة. تحسين كفاءة تنظيم الجلسات. | J30: — | K30: الإدارة العامة لأنظمة الاختبارات | L30: — | M30: الأعمال | N30: تشغيلي | O30: متوسطة | P30: 46388 | Q30: — | R30: ملغي | S30: 0 | T30: 300000000
A31: 30 | B31: توفير خدمة اختبارات بالكبائن الذكية | C31: 1. دعم اتخاذ القرارات 3. تمكين التحول الرقمي 4. دعم تحسين تجربة المستفيد | D31: 3. تعزيز الابتكار الرقمي المؤسسي من خلال استثمار التقنيات الناشئة والتحليلات المتقدمة والذكاء الاصطناعي لتطوير حلول رقمية فعّالة لدعم جودة التقويم والتعليم والتدريب، وتسهم في تحسين الكفاءة التشغيلية وتجربة المستفيد 5. تحقيق التميز في تقديم الخدمات الرقمية من خلال التوسع في رقمنة الخدمات، وتحسين تجربة المستفيدين بما يضمن الامتثال لمعايير الحكومة الرقمية | E31: تحسين تجربة المستفيد وتوحيد مسار ات تقديم الخدمات الرقمية ◂ 1. مبادرة الذكاء الاصطناعي والتحليلات المتقدمة | F31: GAP-A-06، GAP-B-01، GAP-B-17، GAP-B-20، GAP-B-21، GAP-B-22، GAP-B-24، GAP-B-25، GAP-D-17 | G31: AR18، BR02، TR01 | H31: كبائن ذكية من مقعد واحد لتطبيق الاختبارات, تعتمد في تشغيلها على تقنيات الذكاء الاصطناعي و المراقبة عن بعد | I31: توفير حلول اختبار مرنة وذاتية الخدمة. تقليل الحاجة إلى مراقبين بشريين. تعزيز الأمان والتحقق الرقمي. دعم الوصول للمناطق النائية. | J31: • تقديم خدمة أداء الاختبارات الرقمية بالرياض ، الدمام ، المدينة المنورة ، الطائف ، بريدة ، الهفوف ،جازان ، جدة • توفير خدمة للتعلم الإلكتروني جاهزة للاستخدام • توفير خدمة الاشتراك في موقع إلكتروني لتقديم خدمات الدعم والأبحاث التقنية | K31: الإدارة العامة لأنظمة الاختبارات | L31: — | M31: الأعمال و البيانات | N31: تشغيلي | O31: متوسطة | P31: 46023 | Q31: 46753 | R31: لم يبدأ | S31: 0 | T31: 2300000
A32: 31 | B32: تفعيل الابتكار الرقمي في بناء منتجات ابتكارية جديدة | C32: 3. تمكين التحول الرقمي 4. دعم تحسين تجربة المستفيد | D32: 3. تعزيز الابتكار الرقمي المؤسسي من خلال استثمار التقنيات الناشئة والتحليلات المتقدمة والذكاء الاصطناعي لتطوير حلول رقمية فعّالة لدعم جودة التقويم والتعليم والتدريب، وتسهم في تحسين الكفاءة التشغيلية وتجربة المستفيد 5. تحقيق التميز في تقديم الخدمات الرقمية من خلال التوسع في رقمنة الخدمات، وتحسين تجربة المستفيدين بما يضمن الامتثال لمعايير الحكومة الرقمية | E32: تحفيز الابتكار الرقمي ◂ 1. مبادرة الذكاء الاصطناعي والتحليلات المتقدمة | F32: GAP-B-04، GAP-B-09، GAP-B-15، GAP-B-16، GAP-B-17، GAP-B-18، GAP-B-20 | G32: AR18، BR02، BR07 | H32: منافسة تفعيل الابتكار الرقمي في بناء منتجات ابتكارية جديدة | I32: تطوير أدوات تقييم غير تقليدية. تعزيز تجربة المستخدم عبر حلول مبتكرة. دعم بناء نماذج متقدمة في التقويم. تحفيز بيئة العمل على الابتكار والتحول. | J32: — | K32: الإدارة العامة لأنظمة الاختبارات | L32: — | M32: الأعمال | N32: تشغيلي | O32: متوسطة | P32: 46478 | Q32: 47209 | R32: لم يبدأ | S32: 0 | T32: 3000000
A33: 32 | B33: توفير أدوات ذكاء الأعمال والتحليلات المتقدمة لدعم اتخاذ القرار المبني على البيانات | C33: 1. دعم اتخاذ القرارات 4. دعم تحسين تجربة المستفيد 6. المواءمة الاستراتيجية | D33: 3. تعزيز الابتكار الرقمي المؤسسي من خلال استثمار التقنيات الناشئة والتحليلات المتقدمة والذكاء الاصطناعي لتطوير حلول رقمية فعّالة لدعم جودة التقويم والتعليم والتدريب، وتسهم في تحسين الكفاءة التشغيلية وتجربة المستفيد 5. تحقيق التميز في تقديم الخدمات الرقمية من خلال التوسع في رقمنة الخدمات، وتحسين تجربة المستفيدين بما يضمن الامتثال لمعايير الحكومة الرقمية | E33: رفع كفاءة اتخاذ القرار المبني على البيانات ◂ 1. مبادرة الذكاء الاصطناعي والتحليلات المتقدمة | F33: GAP-A-10، GAP-B-07، GAP-B-11، GAP-B-12، GAP-B-18، GAP-D-07، GAP-D-17، GAP-D-20، GAP-D-23 | G33: AR02، AR08 | H33: توفير أدوات للتحليلات المتقدمة ذاتية الخدمة ولعرض وتصوير البيانات ولوحات المعلومات | I33: تمكين تحليل فوري وشامل للبيانات. دعم اتخاذ القرار الاستراتيجي. توفير لوحات تحكم مرئية تفاعلية. تحسين مؤشرات الأداء المؤسسي. | J33: — | K33: الإدارة العامة للبيانات والذكاء الاصطناعي | L33: — | M33: الأعمال و البيانات | N33: تشغيلي | O33: متوسطة | P33: 46023 | Q33: 46023 | R33: ملغي | S33: 0 | T33: 2000000
A34: 33 | B34: توريد وتركيب أدوات إدارة البيانات الوصفية والبيانات الرئيسية والمرجعية | C34: 1. دعم اتخاذ القرارات 5. تعزيز الحوكمة المؤسسية 6. المواءمة الاستراتيجية | D34: 1. الامتثال للسياسات ذات العلاقة بمجال البيانات والتحول الرقمي الناشئ من أنظمة الهيئة وخدماتها، ومع تعزيز الاستفادة من البيانات والأنظمة لدعم أعمال الهيئة 2. تمكين التكامل التقني مع الجهات الحكومية ذات العلاقة عبر قنوات البيانات الوطنية، لتبادل البيانات وتقديم خدمات موحدة ومترابطة للمستفيدين 3. تعزيز الابتكار الرقمي المؤسسي من خلال استثمار التقنيات الناشئة والتحليلات المتقدمة والذكاء الاصطناعي لتطوير حلول رقمية فعّالة لدعم جودة التقويم والتعليم والتدريب، وتسهم في تحسين الكفاءة التشغيلية وتجربة المستفيد | E34: تحسين جودة وتكامل البيانات وفق المعايير الوطنية ◂ 1. مبادرة الذكاء الاصطناعي والتحليلات المتقدمة | F34: GAP-A-01، GAP-A-09، GAP-A-10، GAP-B-02، GAP-B-05، GAP-B-06، GAP-B-10، GAP-B-13، GAP-D-01، GAP-D-02، GAP-D-04، GAP-D-05، GAP-D-07، GAP-D-10، GAP-D-17، GAP-D-18، GAP-D-20، GAP-D-23، GAP-D-24، GAP-D-25، GAP-D-30، GAP-D-31 | G34: AR02، AR05، BR01، DR01، DR02 | H34: توريد وتركيب أدوات إدارة البيانات الوصفية والبيانات الرئيسية والمرجعية حسب متطلبات مكتب البيانات الوطنية | I34: تحسين جودة وتكامل البيانات. تسهيل إدارة دورة حياة البيانات. دعم الحوكمة والامتثال التنظيمي. تمكين التحليلات الذكية والربط بين الأنظمة. | J34: • توريد وتركيب أنظمة إدارة وحوكمة البيانات | K34: الإدارة العامة للبيانات والذكاء الاصطناعي | L34: — | M34: البيانات | N34: تشغيلي | O34: متوسطة | P34: 46023 | Q34: 46023 | R34: ملغي | S34: 0 | T34: 5000000
A35: 34 | B35: رفع مستوى نضج تطبيق ممارسات إدارة البيانات | C35: 1. دعم اتخاذ القرارات 3. تمكين التحول الرقمي 5. تعزيز الحوكمة المؤسسية | D35: 1. الامتثال للسياسات ذات العلاقة بمجال البيانات والتحول الرقمي الناشئ من أنظمة الهيئة وخدماتها، ومع تعزيز الاستفادة من البيانات والأنظمة لدعم أعمال الهيئة 3. تعزيز الابتكار الرقمي المؤسسي من خلال استثمار التقنيات الناشئة والتحليلات المتقدمة والذكاء الاصطناعي لتطوير حلول رقمية فعّالة لدعم جودة التقويم والتعليم والتدريب، وتسهم في تحسين الكفاءة التشغيلية وتجربة المستفيد 5. تحقيق التميز في تقديم الخدمات الرقمية من خلال التوسع في رقمنة الخدمات، وتحسين تجربة المستفيدين بما يضمن الامتثال لمعايير الحكومة الرقمية | E35: ◂ 1. مبادرة الذكاء الاصطناعي والتحليلات المتقدمة | F35: GAP-B-01، GAP-B-20، GAP-B-21، GAP-B-22، GAP-B-24، GAP-B-25، GAP-D-01، GAP-D-02، GAP-D-13، GAP-D-24، GAP-D-25، GAP-D-30، GAP-D-31 | G35: AR05، AR18، BR02، BR11 | H35: تقديم خدمات استشارية لرقع مستوى النضج والامتثال لضوابط ومواصفات إدارة البيانات الوطنية | I35: دعم اتخاذ القرار المبني على البيانات • تعزيز القدرات التحليلية للهيئة • تحسين تجربة المستفيد • تسهيل الوصول إلى الخدمات الرقمية | J35: • توريد وتركيب أدوات إدارة البيانات الوصفية والبيانات الرئيسية والمرجعية • مشروع تنفيذ بند تشغيل وصيانة البنية التقنية لمنافسة مشروع تشغيل وصيانة البنية التقنية والبيانات وتطبيق الذكاء • مشروع تنفيذ بند تشغيل وصيانة البنية التقنية لمنافسة مشروع تشغيل وصيانة البنية التقنية والبيانات وتطبيق الذكاء(تجديد العقد) | K35: — | L35: — | M35: الأعمال و التطبيقات والبيانات | N35: تشغيلي | O35: منخفضة | P35: 46023 | Q35: 46753 | R35: ملغي | T35: 2000000
A36: 35 | B36: المساعد الرقمي للعناية بالمستفيدين | C36: 1. دعم اتخاذ القرارات 3. تمكين التحول الرقمي 4. دعم تحسين تجربة المستفيد | D36: 2. تمكين التكامل التقني مع الجهات الحكومية ذات العلاقة عبر قنوات البيانات الوطنية، لتبادل البيانات وتقديم خدمات موحدة ومترابطة للمستفيدين 3. تعزيز الابتكار الرقمي المؤسسي من خلال استثمار التقنيات الناشئة والتحليلات المتقدمة والذكاء الاصطناعي لتطوير حلول رقمية فعّالة لدعم جودة التقويم والتعليم والتدريب، وتسهم في تحسين الكفاءة التشغيلية وتجربة المستفيد 5. تحقيق التميز في تقديم الخدمات الرقمية من خلال التوسع في رقمنة الخدمات، وتحسين تجربة المستفيدين بما يضمن الامتثال لمعايير الحكومة الرقمية | E36: ◂ 1. مبادرة الذكاء الاصطناعي والتحليلات المتقدمة | F36: GAP-A-01، GAP-A-09، GAP-B-04، GAP-B-05، GAP-B-09، GAP-B-15، GAP-B-16، GAP-B-17، GAP-D-07، GAP-D-17، GAP-D-20، GAP-D-23، GAP-T-20 | G36: AR08، AR18، BR04، BR16 | H36: نظام المساعد الرقمي بإستخدام الذكاء الاصطناعي التوليدي للعناية بالمستفيدين وذلك بالإجابة عن استفسارات الفئات المستفيدة حول الخدمات المقدمة. مع تكامله مع أنظمة الهيئة ونشره على جميع قنوات التواصل بالهيئة | I36: تحسين تجربة المستفيد • تسهيل الوصول إلى الخدمات الرقمية | J36: — | K36: — | L36: — | M36: التطبيقات | N36: رأسمالي | O36: منخفضة | P36: 46478 | Q36: 47209 | R36: لم يبدأ | S36: 0 | T36: 2000000
A37: 36 | B37: مشروع تنفيذ بند تشغيل وصيانة البنية التقنية لمنافسة مشروع تشغيل وصيانة البنية التقنية والبيانات وتطبيق الذكاء | C37: 1. دعم اتخاذ القرارات 2. تعزيز الكفاءة التشغيلية وكفاءة الإنفاق 3. تمكين التحول الرقمي | D37: 2. تمكين التكامل التقني مع الجهات الحكومية ذات العلاقة عبر قنوات البيانات الوطنية، لتبادل البيانات وتقديم خدمات موحدة ومترابطة للمستفيدين 3. تعزيز الابتكار الرقمي المؤسسي من خلال استثمار التقنيات الناشئة والتحليلات المتقدمة والذكاء الاصطناعي لتطوير حلول رقمية فعّالة لدعم جودة التقويم والتعليم والتدريب، وتسهم في تحسين الكفاءة التشغيلية وتجربة المستفيد 4. بناء قدرات رقمية وطنية وتمكين الكفاءات المتخصصة والعامة في مجال البيانات والتحول الرقمي، من خلال مسارات تدريبية مستهدفة متوافقة مع معايير بناء الكفاءات | E37: تنفيذ خطة البيانات والذكاء الاصطناعي وتطبيقها ◂ 2. مبادرة الجاهزية التشغيلية واستمرارية الأعمال | F37: GAP-A-01، GAP-A-09، GAP-A-10، GAP-B-01، GAP-B-05، GAP-B-14، GAP-B-20، GAP-B-21، GAP-B-22، GAP-B-24، GAP-B-25، GAP-B-28، GAP-D-07، GAP-D-17، GAP-D-20، GAP-D-23 | G37: AR02، AR18، BR06 | H37: تشغيل وصيانة البنية التقنية ونظم البيانات والتكامل وذكاء الاعمال وتطبيق ألف ياء للذكاء في هيئة تقويم التعليم والتدريب | I37: تشغيل وصيانة نظم البيانات والتكامل وذكاء الأعمال | J37: • مشروع تنفيذ بند تشغيل وصيانة البنية التقنية لمنافسة مشروع تشغيل وصيانة البنية التقنية والبيانات وتطبيق الذكاء(تجديد العقد) | K37: الإدارة العامة للبيانات والذكاء الاصطناعي | L37: شركة بحر العرب لأنظمة المعلومات | M37: البيانات والتقنية | N37: تشغيلي | O37: متوسطة | P37: 24/2/2024 | Q37: 26/2/2028 | R37: قائم | S37: 0 | T37: 16974000
A38: 37 | B38: مشروع تنفيذ بند تشغيل وصيانة البنية التقنية لمنافسة مشروع تشغيل وصيانة البنية التقنية والبيانات وتطبيق الذكاء(تجديد العقد) | C38: 1. دعم اتخاذ القرارات 2. تعزيز الكفاءة التشغيلية وكفاءة الإنفاق 3. تمكين التحول الرقمي | D38: 2. تمكين التكامل التقني مع الجهات الحكومية ذات العلاقة عبر قنوات البيانات الوطنية، لتبادل البيانات وتقديم خدمات موحدة ومترابطة للمستفيدين 3. تعزيز الابتكار الرقمي المؤسسي من خلال استثمار التقنيات الناشئة والتحليلات المتقدمة والذكاء الاصطناعي لتطوير حلول رقمية فعّالة لدعم جودة التقويم والتعليم والتدريب، وتسهم في تحسين الكفاءة التشغيلية وتجربة المستفيد 6. تنظيم الاستفادة من البنية التحتية التقنية بما يضمن استمرارية الأعمال وحوكمة الكفاءة التشغيلية | E38: تنفيذ خطة البيانات والذكاء الاصطناعي وتطبيقها ◂ 2. مبادرة الجاهزية التشغيلية واستمرارية الأعمال | F38: GAP-A-01، GAP-A-09، GAP-A-10، GAP-B-01، GAP-B-05، GAP-B-14، GAP-B-20، GAP-B-21، GAP-B-22، GAP-B-24، GAP-B-25، GAP-B-28، GAP-D-07، GAP-D-17، GAP-D-20، GAP-D-23 | G38: AR02، AR18، BR06 | H38: تشغيل وصيانة البنية التقنية ونظم البيانات والتكامل وذكاء الاعمال وتطبيق ألف ياء للذكاء في هيئة تقويم التعليم والتدريب | I38: تشغيل وصيانة نظم البيانات والتكامل وذكاء الأعمال | J38: • مشروع تنفيذ بند تشغيل وصيانة البنية التقنية لمنافسة مشروع تشغيل وصيانة البنية التقنية والبيانات وتطبيق الذكاء | K38: الإدارة العامة للبيانات والذكاء الاصطناعي | L38: شركة بحر العرب لأنظمة المعلومات | M38: البيانات والتقنية | N38: تشغيلي | O38: متوسطة | P38: 27/2/2028 | Q38: — | R38: ملغي | S38: 0 | T38: 16974000
A39: 38 | B39: تعزيز الجاهزية المؤسسية لاستمرارية الأعمال- المرحلة الأولى | C39: 2. تعزيز الكفاءة التشغيلية وكفاءة الإنفاق 3. تمكين التحول الرقمي 4. دعم تحسين تجربة المستفيد | D39: 5. تحقيق التميز في تقديم الخدمات الرقمية من خلال التوسع في رقمنة الخدمات، وتحسين تجربة المستفيدين بما يضمن الامتثال لمعايير الحكومة الرقمية 6. تنظيم الاستفادة من البنية التحتية التقنية بما يضمن استمرارية الأعمال وحوكمة الكفاءة التشغيلية | E39: رفع جاهزية واستدامة البنية التحتية التقنية ◂ 3. مبادرة تعزيز كفاءة واستدامة البنية التحتية التقنية | F39: GAP-A-04، GAP-B-01، GAP-B-04، GAP-B-09، GAP-B-15، GAP-B-16، GAP-B-17، GAP-B-20، GAP-B-21، GAP-B-22، GAP-B-23، GAP-B-24، GAP-B-25، GAP-D-03، GAP-D-11، GAP-D-12، GAP-T-8، GAP-T-15 | G39: BR04، TR03 | H39: بناء وتنفيذ خطة استمررية الاعمال و التحول السحابي لانظمة اختبارات جاهزية ومستقبلهم ونظام نمر | I39: تقليل تأثير الأزمات والطوارئ على الأنشطة التشغيلية. تحسين مرونة الأعمال واستعدادها. تعزيز ثقة أصحاب العلاقة في كفاءة الهيئة. ضمان استدامة تقديم الخدمات الحيوية. | J39: — | K39: الإدارة العامة لتقنية المعلومات | L39: — | M39: التقنية | N39: تشغيلي | O39: متوسطة | P39: 46023 | Q39: 46753 | R39: لم يبدأ | S39: 0 | T39: 5000000
A40: 39 | B40: تحسين أداء شبكة WAN باستخدام حلول تسريع الاتصالات (Riverbed) | C40: 1. دعم اتخاذ القرارات 2. تعزيز الكفاءة التشغيلية وكفاءة الإنفاق 3. تمكين التحول الرقمي | D40: 3. تعزيز الابتكار الرقمي المؤسسي من خلال استثمار التقنيات الناشئة والتحليلات المتقدمة والذكاء الاصطناعي لتطوير حلول رقمية فعّالة لدعم جودة التقويم والتعليم والتدريب، وتسهم في تحسين الكفاءة التشغيلية وتجربة المستفيد 5. تحقيق التميز في تقديم الخدمات الرقمية من خلال التوسع في رقمنة الخدمات، وتحسين تجربة المستفيدين بما يضمن الامتثال لمعايير الحكومة الرقمية 6. تنظيم الاستفادة من البنية التحتية التقنية بما يضمن استمرارية الأعمال وحوكمة الكفاءة التشغيلية | E40: رفع جاهزية واستدامة البنية التحتية التقنية ◂ 3. مبادرة تعزيز كفاءة واستدامة البنية التحتية التقنية | F40: GAP-B-01، GAP-B-04، GAP-B-09، GAP-B-15، GAP-B-16، GAP-B-17، GAP-B-20، GAP-B-21، GAP-B-22، GAP-B-24، GAP-B-25، GAP-T-7، GAP-T-17 | G40: BR10، DR02، TR04 | H40: تسريع التطبيقات، تحسين أداء السحابة و مرجعية البيانات القابلة للتطوير، تحسين حركة المرور المشفرة، وتحسين تكرار البيانات والتخزين. | I40: تسريع نقل البيانات بين المواقع. تقليل زمن تحميل الأنظمة والتطبيقات. تحسين تجربة المستخدم النهائي. تعزيز كفاءة الشبكة في المواقع البعيدة. | J40: — | K40: الإدارة العامة لتقنية المعلومات | L40: — | M40: التقنية | N40: تشغيلي | O40: متوسطة | P40: 46569 | Q40: 47665 | R40: لم يبدأ | S40: 0 | T40: 5000000
...

Sheet ملخص التغطية
A5: توزيع المشاريع على الإدارات المالكة
A6: # | B6: الإدارة | C6: عدد المشاريع | D6: إجمالي الميزانية (ريال)
A7: 1 | C7: 43 | D7: 9.5581002e+08
A8: 2 | B8: الإدارة العامة لتقنية المعلومات | C8: 32 | D8: 3.6969553e+08
A9: 3 | B9: قطاع البيانات والتحول الرقمي | C9: 14 | D9: 1.7613157e+08
A10: 4 | B10: الإدارة العامة للتطوير | C10: 11 | D10: 89991218
A11: 5 | B11: الإدارة العامة للبيانات والذكاء الاصطناعي | C11: 10 | D11: 55411789
A12: 6 | B12: الإدارة العامة لأنظمة الاختبارات | C12: 5 | D12: 316212000
A13: 7 | B13: مركز قياس | C13: 3 | D13: 3.8706258e+08
A14: 8 | B14: إدارة التخطيط و الجودة | C14: 3 | D14: 54500000
A15: 9 | B15: الإدارة العامة للتخطيط و التميز المؤسسي | C15: 2 | D15: 6000000
A16: 10 | B16: مركز تميّز | C16: 1 | D16: 0
A17: 11 | B17: الإدارة العامة للموارد البشرية | C17: 1 | D17: 2000000
B18: الإجمالي | C18: =SUM(C7:C17) -> 125 | D18: =SUM(D7:D17) -> 2.4128147e+09

Sheet مرجع الأهداف
A1: أهداف البنية المؤسسية (6)
A2: # | B2: الهدف | C2: عدد المشاريع
A3: 1 | B3: دعم اتخاذ القرارات | C3: =SUMPRODUCT(--ISNUMBER(SEARCH("1. ",'مصفوفة الربط'!C2:C126))) -> 42
A4: 2 | B4: تعزيز الكفاءة التشغيلية وكفاءة الإنفاق | C4: =SUMPRODUCT(--ISNUMBER(SEARCH("2. ",'مصفوفة الربط'!C2:C126))) -> 82
A5: 3 | B5: تمكين التحول الرقمي | C5: =SUMPRODUCT(--ISNUMBER(SEARCH("3. ",'مصفوفة الربط'!C2:C126))) -> 81
A6: 4 | B6: دعم تحسين تجربة المستفيد | C6: =SUMPRODUCT(--ISNUMBER(SEARCH("4. ",'مصفوفة الربط'!C2:C126))) -> 53
A7: 5 | B7: تعزيز الحوكمة المؤسسية | C7: =SUMPRODUCT(--ISNUMBER(SEARCH("5. ",'مصفوفة الربط'!C2:C126))) -> 37
A8: 6 | B8: المواءمة الاستراتيجية | C8: =SUMPRODUCT(--ISNUMBER(SEARCH("6. ",'مصفوفة الربط'!C2:C126))) -> 24
A10: أهداف التحول الرقمي (6)
A11: # | B11: الهدف | C11: عدد المشاريع
A12: 1 | B12: الامتثال للسياسات ذات العلاقة بمجال البيانات والتحول الرقمي الناشئ من أنظمة الهيئة وخدماتها، ومع تعزيز الاستفادة من البيانات والأنظمة لدعم أعمال الهيئة | C12: =SUMPRODUCT(--ISNUMBER(SEARCH("1. ",'مصفوفة الربط'!D2:D126))) -> 52
A13: 2 | B13: تمكين التكامل التقني مع الجهات الحكومية ذات العلاقة عبر قنوات البيانات الوطنية، لتبادل البيانات وتقديم خدمات موحدة ومترابطة للمستفيدين | C13: =SUMPRODUCT(--ISNUMBER(SEARCH("2. ",'مصفوفة الربط'!D2:D126))) -> 28
A14: 3 | B14: تعزيز الابتكار الرقمي المؤسسي من خلال استثمار التقنيات الناشئة والتحليلات المتقدمة والذكاء الاصطناعي لتطوير حلول رقمية فعّالة لدعم جودة التقويم والتعليم والتدريب، وتسهم في تحسين الكفاءة التشغيلية وتجربة المستفيد | C14: =SUMPRODUCT(--ISNUMBER(SEARCH("3. ",'مصفوفة الربط'!D2:D126))) -> 52
A15: 4 | B15: بناء قدرات رقمية وطنية وتمكين الكفاءات المتخصصة والعامة في مجال البيانات والتحول الرقمي، من خلال مسارات تدريبية مستهدفة متوافقة مع معايير بناء الكفاءات | C15: =SUMPRODUCT(--ISNUMBER(SEARCH("4. ",'مصفوفة الربط'!D2:D126))) -> 20
A16: 5 | B16: تحقيق التميز في تقديم الخدمات الرقمية من خلال التوسع في رقمنة الخدمات، وتحسين تجربة المستفيدين بما يضمن الامتثال لمعايير الحكومة الرقمية | C16: =SUMPRODUCT(--ISNUMBER(SEARCH("5. ",'مصفوفة الربط'!D2:D126))) -> 83
A17: 6 | B17: تنظيم الاستفادة من البنية التحتية التقنية بما يضمن استمرارية الأعمال وحوكمة الكفاءة التشغيلية | C17: =SUMPRODUCT(--ISNUMBER(SEARCH("6. ",'مصفوفة الربط'!D2:D126))) -> 56
A20: مبادرات التحول الرقمي الاستراتيجية (6)
A21: # | B21: المبادرة | C21: عدد المشاريع
A22: 1 | B22: مبادرة الذكاء الاصطناعي والتحليلات المتقدمة | C22: =SUMPRODUCT(--ISNUMBER(SEARCH("1. ",'مصفوفة الربط'!E2:E126))) -> 16
A23: 2 | B23: مبادرة الجاهزية التشغيلية واستمرارية الأعمال | C23: =SUMPRODUCT(--ISNUMBER(SEARCH("2. ",'مصفوفة الربط'!E2:E126))) -> 21
A24: 3 | B24: مبادرة تعزيز كفاءة واستدامة البنية التحتية التقنية | C24: =SUMPRODUCT(--ISNUMBER(SEARCH("3. ",'مصفوفة الربط'!E2:E126))) -> 35
A25: 4 | B25: مبادرة تطوير الحلول والخدمات الرقمية | C25: =SUMPRODUCT(--ISNUMBER(SEARCH("4. ",'مصفوفة الربط'!E2:E126))) -> 33
A26: 5 | B26: مبادرة تحسين تجربة المستفيد الرقمية | C26: =SUMPRODUCT(--ISNUMBER(SEARCH("5. ",'مصفوفة الربط'!E2:E126))) -> 15
A27: 6 | B27: مبادرة التمكين الرقمي | C27: =SUMPRODUCT(--ISNUMBER(SEARCH("6. ",'مصفوفة الربط'!E2:E126))) -> 11

Sheet مرجع المتطلبات
A1: المتطلبات المؤسسية
A2: الرمز | B2: النوع | C2: النص | D2: عدد المشاريع
A3: AR01 | B3: تطبيقات | C3: تطوير نظام تواصل داخلي فعال يقلل الاعتماد على البريد الإلكتروني | D3: =COUNTIF('مصفوفة الربط'!G2:G126,"*AR01*") -> 2
A4: AR02 | B4: تطبيقات | C4: توفير نظام مركزي لمتابعة الأداء وتحليل البيانات | D4: =COUNTIF('مصفوفة الربط'!G2:G126,"*AR02*") -> 11
A5: AR03 | B5: تطبيقات | C5: توفير آلية للإبلاغ عن حوادث سرقة البيانات وتدريبات للموظفين | D5: =COUNTIF('مصفوفة الربط'!G2:G126,"*AR03*") -> 2
A6: AR04 | B6: تطبيقات | C6: اعتماد تقنيات متقدمة لتصنيف البيانات | D6: =COUNTIF('مصفوفة الربط'!G2:G126,"*AR04*") -> 2
A7: AR05 | B7: تطبيقات | C7: اعتماد نظام لإدارة جودة البيانات يشمل تعريف البيانات والمؤشرات | D7: =COUNTIF('مصفوفة الربط'!G2:G126,"*AR05*") -> 9
A8: AR06 | B8: تطبيقات | C8: تطوير نظام موحد لتجميع بيانات المستفيدين وتحسين تكامل البيانات | D8: =COUNTIF('مصفوفة الربط'!G2:G126,"*AR06*") -> 4
A9: AR07 | B9: تطبيقات | C9: اعتماد آلية مركزية لإدارة الأصول التقنية | D9: =COUNTIF('مصفوفة الربط'!G2:G126,"*AR07*") -> 32
A10: AR08 | B10: تطبيقات | C10: تطوير نظام تحليل بيانات متكامل لرصد احتياجات المستفيدين | D10: =COUNTIF('مصفوفة الربط'!G2:G126,"*AR08*") -> 9
A11: AR09 | B11: تطبيقات | C11: تنفيذ برامج وأدوات لقياس وتحليل رضا المستفيدين | D11: =COUNTIF('مصفوفة الربط'!G2:G126,"*AR09*") -> 7
A12: AR10 | B12: تطبيقات | C12: تطوير نظام إدارة الإنابة لضمان استمرارية الأعمال | D12: =COUNTIF('مصفوفة الربط'!G2:G126,"*AR10*") -> 2
A13: AR11 | B13: تطبيقات | C13: تطوير نظام متكامل لقياس أداء الإجراءات وربطها بالأهداف الاستراتيجية | D13: =COUNTIF('مصفوفة الربط'!G2:G126,"*AR11*") -> 1
A14: AR12 | B14: تطبيقات | C14: تطوير نظام إدارة مهام يتضمن آلية لتحديد الأولويات | D14: =COUNTIF('مصفوفة الربط'!G2:G126,"*AR12*") -> 2
A15: AR13 | B15: تطبيقات | C15: تطوير نظام لربط إدارة المهام مع إدارة الأداء | D15: =COUNTIF('مصفوفة الربط'!G2:G126,"*AR13*") -> 1
A16: AR14 | B16: تطبيقات | C16: نظام موحد لاستقبال ومتابعة المقترحات والأفكار والشكاوى | D16: =COUNTIF('مصفوفة الربط'!G2:G126,"*AR14*") -> 2
A17: AR15 | B17: تطبيقات | C17: تطوير منصة موحدة شاملة لأعمال الهيئة | D17: =COUNTIF('مصفوفة الربط'!G2:G126,"*AR15*") -> 2
A18: AR16 | B18: تطبيقات | C18: إنشاء بوابة داخلية موحدة للموظفين | D18: =COUNTIF('مصفوفة الربط'!G2:G126,"*AR16*") -> 3
A19: AR17 | B19: تطبيقات | C19: تطوير نظام متخصص للجودة | D19: =COUNTIF('مصفوفة الربط'!G2:G126,"*AR17*") -> 9
A20: AR18 | B20: تطبيقات | C20: تكامل النظام الجديد مع الأنظمة الحالية | D20: =COUNTIF('مصفوفة الربط'!G2:G126,"*AR18*") -> 39
A21: AR19 | B21: تطبيقات | C21: اعتماد أدوات وتقنيات متقدمة لإدارة المعرفة | D21: =COUNTIF('مصفوفة الربط'!G2:G126,"*AR19*") -> 5
A22: AR20 | B22: تطبيقات | C22: إنشاء نظام مركزي لإدارة المشاريع | D22: =COUNTIF('مصفوفة الربط'!G2:G126,"*AR20*") -> 1
A23: BR01 | B23: أعمال | C23: إعادة هندسة الإجراءات الخاصة بإدارة التغيير على العمليات مع وضع حوكمة فعالة | D23: =COUNTIF('مصفوفة الربط'!G2:G126,"*BR01*") -> 32
A24: BR02 | B24: أعمال | C24: استكمال أتمتة جميع الإجراءات المتبقية لضمان تكامل الخدمات وتحسين الكفاءة التشغيلية | D24: =COUNTIF('مصفوفة الربط'!G2:G126,"*BR02*") -> 48
A25: BR03 | B25: أعمال | C25: إعادة هندسة الإجراءات الخاصة بإدارة التواصل مع الجهات الحكومية المزودة للخدمات | D25: =COUNTIF('مصفوفة الربط'!G2:G126,"*BR03*") -> 5
A26: BR04 | B26: أعمال | C26: تطوير وتطبيق نموذج متعدد القنوات لدمج قنوات التواصل مع المستفيدين | D26: =COUNTIF('مصفوفة الربط'!G2:G126,"*BR04*") -> 12
A27: BR05 | B27: أعمال | C27: إجراء تقييم دوري لتحديد مستوى الثقافة الرقمية بين الموظفين | D27: =COUNTIF('مصفوفة الربط'!G2:G126,"*BR05*") -> 3
A28: BR06 | B28: أعمال | C28: تطوير وتنفيذ برنامج تدريبي شامل لتعزيز المهارات الرقمية | D28: =COUNTIF('مصفوفة الربط'!G2:G126,"*BR06*") -> 29
A29: BR07 | B29: أعمال | C29: توفير برامج تدريبية لتعزيز الثقافة الرشيقة والابتكار | D29: =COUNTIF('مصفوفة الربط'!G2:G126,"*BR07*") -> 6
A30: BR08 | B30: أعمال | C30: اعتماد وتطبيق منهجيات العمل الرشيقة Agile | D30: =COUNTIF('مصفوفة الربط'!G2:G126,"*BR08*") -> 2
A31: BR09 | B31: أعمال | C31: تصميم وتنفيذ سياسات وإجراءات واضحة للإنابة | D31: =COUNTIF('مصفوفة الربط'!G2:G126,"*BR09*") -> 1
A32: BR10 | B32: أعمال | C32: إعداد وتنفيذ سياسة موحدة لإدارة الأنظمة | D32: =COUNTIF('مصفوفة الربط'!G2:G126,"*BR10*") -> 10
A33: BR11 | B33: أعمال | C33: إجراء مراجعة شاملة لجميع الأنظمة الحالية وخطة لدمج الأنظمة | D33: =COUNTIF('مصفوفة الربط'!G2:G126,"*BR11*") -> 2
A34: BR12 | B34: أعمال | C34: اعتماد مؤشرات أداء رئيسية KPIs لكل إجراء وخدمة | D34: =COUNTIF('مصفوفة الربط'!G2:G126,"*BR12*") -> 1
A35: BR13 | B35: أعمال | C35: دليل حوكمة الإجراءات ومصفوفة الصلاحيات واتفاقيات OLA و SLA | D35: =COUNTIF('مصفوفة الربط'!G2:G126,"*BR13*") -> 1
A36: BR14 | B36: أعمال | C36: إعداد سياسة واضحة لتحديد أولويات العمل | D36: =COUNTIF('مصفوفة الربط'!G2:G126,"*BR14*") -> 2
A37: BR15 | B37: أعمال | C37: سياسة واضحة لتقييم أداء الموظف تشمل ربط المهام بمؤشرات الأداء | D37: =COUNTIF('مصفوفة الربط'!G2:G126,"*BR15*") -> 2
A38: BR16 | B38: أعمال | C38: آلية فعالة لمعالجة ومتابعة المقترحات والشكاوى | D38: =COUNTIF('مصفوفة الربط'!G2:G126,"*BR16*") -> 2
A39: BR17 | B39: أعمال | C39: تطوير وتطبيق استراتيجية إدارة التغيير المؤسسية | D39: =COUNTIF('مصفوفة الربط'!G2:G126,"*BR17*") -> 2
A40: BR18 | B40: أعمال | C40: تطوير وتطبيق استراتيجية إدارة المخاطر المؤسسية | D40: =COUNTIF('مصفوفة الربط'!G2:G126,"*BR18*") -> 10
...

Sheet مرجع الفجوات
A1: الفجوات المؤسسية
A2: الرمز | B2: المجال | C2: النص | D2: عدد المشاريع
A3: GAP-A-01 | B3: فجوات بنية التطبيقات | C3: غياب التكامل الشامل بين معظم التطبيقات؛ تكامل أحادي أو غير موثق. | D3: =COUNTIF('مصفوفة الربط'!F2:F126,"*GAP-A-01*") -> 27
A4: GAP-A-02 | B4: فجوات بنية التطبيقات | C4: ضعف التوثيق في العديد من التطبيقات | D4: =COUNTIF('مصفوفة الربط'!F2:F126,"*GAP-A-02*") -> 9
A5: GAP-A-03 | B5: فجوات بنية التطبيقات | C5: ضعف التوثيق الأمني في العديد من التطبيقات: تشفير البيانات والمصادقة المتقدمة | D5: =COUNTIF('مصفوفة الربط'!F2:F126,"*GAP-A-03*") -> 11
A6: GAP-A-04 | B6: فجوات بنية التطبيقات | C6: عدم استثمار كامل للإمكانات السحابية وعناصر البنية التحتية الحديثة Microservices، الحاويات Containers . | D6: =COUNTIF('مصفوفة الربط'!F2:F126,"*GAP-A-04*") -> 4
A7: GAP-A-05 | B7: فجوات بنية التطبيقات | C7: تطبيقات عديمة الاستخدام أو غير فعالة تشكِّل عبئًا تقنيًا وتشغيليًا | D7: =COUNTIF('مصفوفة الربط'!F2:F126,"*GAP-A-05*") -> 7
