Workbook

Sheet Dashboard
A1: لوحة متابعة (Dashboard) — الفجوات والمتطلبات والمشاريع
A3: إجمالي المشاريع | C3: المشاريع المتأخرة (متأخر/متأخر جدا) | E3: متوسط إغلاق المتطلبات | G3: متوسط إغلاق الفجوات
A4: =COUNTIF('متابعة المشاريع'!$A$2:$A$1003,"<>") -> 68 | C4: =COUNTIF('متابعة المشاريع'!$E$2:$E$1003,"متأخر")+COUNTIF('متابعة المشاريع'!$E$2:$E$1003,"متأخر جدا") -> 2 | E4: =IFERROR(AVERAGEIF('متابعة المتطلبات'!$A$2:$A$47,"<>",'متابعة المتطلبات'!$K$2:$K$47),0) -> 0.3525337 | G4: =IFERROR(AVERAGEIF(الفجوات!$A$2:$A$93,"<>",الفجوات!$F$2:$F$93),0) -> 0.207425
A6: أعلى فجوات متأخرة
A7: # | B7: رمز الفجوة | C7: النص | D7: نسبة الإغلاق | E7: عدد المشاريع | F7: المشاريع المتأخرة | G7: أعلى حالة تأخير | H7: المشاريع المرتبطة
A8: 1 | B8: GAP-A-01 | C8: غياب التكامل الشامل بين معظم التطبيقات؛ تكامل أحادي أو غير موثق. | D8: =IF($B8="","",IFERROR(VLOOKUP($B8,الفجوات!$A$2:$F$93,6,FALSE),0)) -> 0 | E8: =IF($B8="","",COUNTIF(Link_Project_Gap!$B$2:$B$112,$B8)) -> 1 | F8: =IF($B8="","",COUNTIFS(Link_Project_Gap!$B$2:$B$112,$B8,Link_Project_Gap!$D$2:$D$112,"متأخر")+COUNTIFS(Link_Project_Gap!$B$2:$B$112,$B8,Link_Project_Gap!$D$2:$D$112,"متأخر جدا")) -> 0 | G8: =IF($B8="","",IF(COUNTIFS(Link_Project_Gap!$B$2:$B$112,$B8,Link_Project_Gap!$D$2:$D$112,"متأخر جدا")>0,"متأخر جدا",IF(COUNTIFS(Link_Project_Gap!$B$2:$B$112,$B8,Link_Project_Gap!$D$2:$D$112,"متأخر")>0,"متأخر","غير متأخر"))) -> غير متأخر | H8: =IF($B8="","",IFERROR(VLOOKUP($B8,الفجوات!$A$2:$E$93,5,FALSE),"")) -> الخدمات الاستشارية المدارة لتعزيز إدارة دورة حياة البرمجيات
A9: 2 | B9: GAP-D-07 | C9: توفر قدرات تحليلية متقدمة غير مفعلة على مستوى الهيئة | D9: =IF($B9="","",IFERROR(VLOOKUP($B9,الفجوات!$A$2:$F$93,6,FALSE),0)) -> 0 | E9: =IF($B9="","",COUNTIF(Link_Project_Gap!$B$2:$B$112,$B9)) -> 1 | F9: =IF($B9="","",COUNTIFS(Link_Project_Gap!$B$2:$B$112,$B9,Link_Project_Gap!$D$2:$D$112,"متأخر")+COUNTIFS(Link_Project_Gap!$B$2:$B$112,$B9,Link_Project_Gap!$D$2:$D$112,"متأخر جدا")) -> 0 | G9: =IF($B9="","",IF(COUNTIFS(Link_Project_Gap!$B$2:$B$112,$B9,Link_Project_Gap!$D$2:$D$112,"متأخر جدا")>0,"متأخر جدا",IF(COUNTIFS(Link_Project_Gap!$B$2:$B$112,$B9,Link_Project_Gap!$D$2:$D$112,"متأخر")>0,"متأخر","غير متأخر"))) -> غير متأخر | H9: =IF($B9="","",IFERROR(VLOOKUP($B9,الفجوات!$A$2:$E$93,5,FALSE),"")) -> رفع مستوى نضج تطبيق ممارسات إدارة البيانات
A10: 3 | B10: GAP-D-09 | C10: استمرار بعض التعاملات الورقية | D10: =IF($B10="","",IFERROR(VLOOKUP($B10,الفجوات!$A$2:$F$93,6,FALSE),0)) -> 0 | E10: =IF($B10="","",COUNTIF(Link_Project_Gap!$B$2:$B$112,$B10)) -> 1 | F10: =IF($B10="","",COUNTIFS(Link_Project_Gap!$B$2:$B$112,$B10,Link_Project_Gap!$D$2:$D$112,"متأخر")+COUNTIFS(Link_Project_Gap!$B$2:$B$112,$B10,Link_Project_Gap!$D$2:$D$112,"متأخر جدا")) -> 0 | G10: =IF($B10="","",IF(COUNTIFS(Link_Project_Gap!$B$2:$B$112,$B10,Link_Project_Gap!$D$2:$D$112,"متأخر جدا")>0,"متأخر جدا",IF(COUNTIFS(Link_Project_Gap!$B$2:$B$112,$B10,Link_Project_Gap!$D$2:$D$112,"متأخر")>0,"متأخر","غير متأخر"))) -> غير متأخر | H10: =IF($B10="","",IFERROR(VLOOKUP($B10,الفجوات!$A$2:$E$93,5,FALSE),"")) -> رفع مستوى نضج تطبيق ممارسات إدارة البيانات
A11: 4 | B11: GAP-D-15 | C11: الاعتماد على إدارة البيانات الورقية بدلًا من الأنظمة المؤتمتة | D11: =IF($B11="","",IFERROR(VLOOKUP($B11,الفجوات!$A$2:$F$93,6,FALSE),0)) -> 0 | E11: =IF($B11="","",COUNTIF(Link_Project_Gap!$B$2:$B$112,$B11)) -> 1 | F11: =IF($B11="","",COUNTIFS(Link_Project_Gap!$B$2:$B$112,$B11,Link_Project_Gap!$D$2:$D$112,"متأخر")+COUNTIFS(Link_Project_Gap!$B$2:$B$112,$B11,Link_Project_Gap!$D$2:$D$112,"متأخر جدا")) -> 0 | G11: =IF($B11="","",IF(COUNTIFS(Link_Project_Gap!$B$2:$B$112,$B11,Link_Project_Gap!$D$2:$D$112,"متأخر جدا")>0,"متأخر جدا",IF(COUNTIFS(Link_Project_Gap!$B$2:$B$112,$B11,Link_Project_Gap!$D$2:$D$112,"متأخر")>0,"متأخر","غير متأخر"))) -> غير متأخر | H11: =IF($B11="","",IFERROR(VLOOKUP($B11,الفجوات!$A$2:$E$93,5,FALSE),"")) -> رفع مستوى نضج تطبيق ممارسات إدارة البيانات
A12: 5 | B12: GAP-T-8 | C12: عدم وجود أهداف موثقة لمؤشرات RTO/RPO | D12: =IF($B12="","",IFERROR(VLOOKUP($B12,الفجوات!$A$2:$F$93,6,FALSE),0)) -> 0 | E12: =IF($B12="","",COUNTIF(Link_Project_Gap!$B$2:$B$112,$B12)) -> 1 | F12: =IF($B12="","",COUNTIFS(Link_Project_Gap!$B$2:$B$112,$B12,Link_Project_Gap!$D$2:$D$112,"متأخر")+COUNTIFS(Link_Project_Gap!$B$2:$B$112,$B12,Link_Project_Gap!$D$2:$D$112,"متأخر جدا")) -> 0 | G12: =IF($B12="","",IF(COUNTIFS(Link_Project_Gap!$B$2:$B$112,$B12,Link_Project_Gap!$D$2:$D$112,"متأخر جدا")>0,"متأخر جدا",IF(COUNTIFS(Link_Project_Gap!$B$2:$B$112,$B12,Link_Project_Gap!$D$2:$D$112,"متأخر")>0,"متأخر","غير متأخر"))) -> غير متأخر | H12: =IF($B12="","",IFERROR(VLOOKUP($B12,الفجوات!$A$2:$E$93,5,FALSE),"")) -> رفع مستوى نضج تطبيق ممارسات إدارة البيانات
A13: 6 | B13: GAP-A-02 | C13: ضعف التوثيق في العديد من التطبيقات | D13: =IF($B13="","",IFERROR(VLOOKUP($B13,الفجوات!$A$2:$F$93,6,FALSE),0)) -> 0 | E13: =IF($B13="","",COUNTIF(Link_Project_Gap!$B$2:$B$112,$B13)) -> 0 | F13: =IF($B13="","",COUNTIFS(Link_Project_Gap!$B$2:$B$112,$B13,Link_Project_Gap!$D$2:$D$112,"متأخر")+COUNTIFS(Link_Project_Gap!$B$2:$B$112,$B13,Link_Project_Gap!$D$2:$D$112,"متأخر جدا")) -> 0 | G13: =IF($B13="","",IF(COUNTIFS(Link_Project_Gap!$B$2:$B$112,$B13,Link_Project_Gap!$D$2:$D$112,"متأخر جدا")>0,"متأخر جدا",IF(COUNTIFS(Link_Project_Gap!$B$2:$B$112,$B13,Link_Project_Gap!$D$2:$D$112,"متأخر")>0,"متأخر","غير متأخر"))) -> غير متأخر | H13: =IF($B13="","",IFERROR(VLOOKUP($B13,الفجوات!$A$2:$E$93,5,FALSE),"")) -> 0
A14: 7 | B14: GAP-A-03 | C14: ضعف التوثيق الأمني في العديد من التطبيقات: تشفير البيانات والمصادقة المتقدمة | D14: =IF($B14="","",IFERROR(VLOOKUP($B14,الفجوات!$A$2:$F$93,6,FALSE),0)) -> 0 | E14: =IF($B14="","",COUNTIF(Link_Project_Gap!$B$2:$B$112,$B14)) -> 0 | F14: =IF($B14="","",COUNTIFS(Link_Project_Gap!$B$2:$B$112,$B14,Link_Project_Gap!$D$2:$D$112,"متأخر")+COUNTIFS(Link_Project_Gap!$B$2:$B$112,$B14,Link_Project_Gap!$D$2:$D$112,"متأخر جدا")) -> 0 | G14: =IF($B14="","",IF(COUNTIFS(Link_Project_Gap!$B$2:$B$112,$B14,Link_Project_Gap!$D$2:$D$112,"متأخر جدا")>0,"متأخر جدا",IF(COUNTIFS(Link_Project_Gap!$B$2:$B$112,$B14,Link_Project_Gap!$D$2:$D$112,"متأخر")>0,"متأخر","غير متأخر"))) -> غير متأخر | H14: =IF($B14="","",IFERROR(VLOOKUP($B14,الفجوات!$A$2:$E$93,5,FALSE),"")) -> 0
A15: 8 | B15: GAP-A-08 | C15: غياب سجل مركزي لتتبع التطبيقات وتقيّدها بمعايير موحَّدة في التطوير والدعم | D15: =IF($B15="","",IFERROR(VLOOKUP($B15,الفجوات!$A$2:$F$93,6,FALSE),0)) -> 0 | E15: =IF($B15="","",COUNTIF(Link_Project_Gap!$B$2:$B$112,$B15)) -> 0 | F15: =IF($B15="","",COUNTIFS(Link_Project_Gap!$B$2:$B$112,$B15,Link_Project_Gap!$D$2:$D$112,"متأخر")+COUNTIFS(Link_Project_Gap!$B$2:$B$112,$B15,Link_Project_Gap!$D$2:$D$112,"متأخر جدا")) -> 0 | G15: =IF($B15="","",IF(COUNTIFS(Link_Project_Gap!$B$2:$B$112,$B15,Link_Project_Gap!$D$2:$D$112,"متأخر جدا")>0,"متأخر جدا",IF(COUNTIFS(Link_Project_Gap!$B$2:$B$112,$B15,Link_Project_Gap!$D$2:$D$112,"متأخر")>0,"متأخر","غير متأخر"))) -> غير متأخر | H15: =IF($B15="","",IFERROR(VLOOKUP($B15,الفجوات!$A$2:$E$93,5,FALSE),"")) -> 0
A16: 9 | B16: GAP-A-09 | C16: عدم استفادة شاملة من Denodo/Talend/CP4D، ونقص في مستودع بيانات مركزي (Data Lake) يتكامل مع كل الأنظمة | D16: =IF($B16="","",IFERROR(VLOOKUP($B16,الفجوات!$A$2:$F$93,6,FALSE),0)) -> 0 | E16: =IF($B16="","",COUNTIF(Link_Project_Gap!$B$2:$B$112,$B16)) -> 0 | F16: =IF($B16="","",COUNTIFS(Link_Project_Gap!$B$2:$B$112,$B16,Link_Project_Gap!$D$2:$D$112,"متأخر")+COUNTIFS(Link_Project_Gap!$B$2:$B$112,$B16,Link_Project_Gap!$D$2:$D$112,"متأخر جدا")) -> 0 | G16: =IF($B16="","",IF(COUNTIFS(Link_Project_Gap!$B$2:$B$112,$B16,Link_Project_Gap!$D$2:$D$112,"متأخر جدا")>0,"متأخر جدا",IF(COUNTIFS(Link_Project_Gap!$B$2:$B$112,$B16,Link_Project_Gap!$D$2:$D$112,"متأخر")>0,"متأخر","غير متأخر"))) -> غير متأخر | H16: =IF($B16="","",IFERROR(VLOOKUP($B16,الفجوات!$A$2:$E$93,5,FALSE),"")) -> 0
A17: 10 | B17: GAP-A-10 | C17: عدم استفادة شاملة من ادوات و تطبيقات ذكاء الأعمال | D17: =IF($B17="","",IFERROR(VLOOKUP($B17,الفجوات!$A$2:$F$93,6,FALSE),0)) -> 0 | E17: =IF($B17="","",COUNTIF(Link_Project_Gap!$B$2:$B$112,$B17)) -> 0 | F17: =IF($B17="","",COUNTIFS(Link_Project_Gap!$B$2:$B$112,$B17,Link_Project_Gap!$D$2:$D$112,"متأخر")+COUNTIFS(Link_Project_Gap!$B$2:$B$112,$B17,Link_Project_Gap!$D$2:$D$112,"متأخر جدا")) -> 0 | G17: =IF($B17="","",IF(COUNTIFS(Link_Project_Gap!$B$2:$B$112,$B17,Link_Project_Gap!$D$2:$D$112,"متأخر جدا")>0,"متأخر جدا",IF(COUNTIFS(Link_Project_Gap!$B$2:$B$112,$B17,Link_Project_Gap!$D$2:$D$112,"متأخر")>0,"متأخر","غير متأخر"))) -> غير متأخر | H17: =IF($B17="","",IFERROR(VLOOKUP($B17,الفجوات!$A$2:$E$93,5,FALSE),"")) -> 0
A19: أعلى متطلبات متأخرة
A20: # | B20: رمز المتطلب | C20: وصف المتطلب | D20: نسبة الإغلاق | E20: عدد المشاريع | F20: المشاريع المتأخرة | G20: أعلى حالة تأخير | H20: المشاريع المرتبطة (اختصار)
A21: 1 | B21: BR07 | C21: توفير برامج تدريبية لتعزيز الثقافة الرشيقة والابتكار بين الموظفين | D21: =IF($B21="","",IFERROR(VLOOKUP($B21,'متابعة المتطلبات'!$A$2:$K$47,11,FALSE),0)) -> 0 | E21: =IF($B21="","",COUNTIF(Link_Project_Req!$B$2:$B$68,$B21)) -> 2 | F21: =IF($B21="","",COUNTIFS(Link_Project_Req!$B$2:$B$68,$B21,Link_Project_Req!$E$2:$E$68,"متأخر")+COUNTIFS(Link_Project_Req!$B$2:$B$68,$B21,Link_Project_Req!$E$2:$E$68,"متأخر جدا")) -> 0 | G21: =IF($B21="","",IF(COUNTIFS(Link_Project_Req!$B$2:$B$68,$B21,Link_Project_Req!$E$2:$E$68,"متأخر جدا")>0,"متأخر جدا",IF(COUNTIFS(Link_Project_Req!$B$2:$B$68,$B21,Link_Project_Req!$E$2:$E$68,"متأخر")>0,"متأخر","غير متأخر"))) -> غير متأخر | H21: =IF($B21="","",IFERROR(VLOOKUP($B21,'متابعة المتطلبات'!$A$2:$J$47,10,FALSE),"")) -> تفعيل الابتكار الرقمي | تحقيق شهادات الجودة
A22: 2 | B22: AR05 | C22: اعتماد نظام لإدارة جودة البيانات يشمل تعريف البيانات والمؤشرات وتجنب تكرار التقارير | D22: =IF($B22="","",IFERROR(VLOOKUP($B22,'متابعة المتطلبات'!$A$2:$K$47,11,FALSE),0)) -> 0 | E22: =IF($B22="","",COUNTIF(Link_Project_Req!$B$2:$B$68,$B22)) -> 1 | F22: =IF($B22="","",COUNTIFS(Link_Project_Req!$B$2:$B$68,$B22,Link_Project_Req!$E$2:$E$68,"متأخر")+COUNTIFS(Link_Project_Req!$B$2:$B$68,$B22,Link_Project_Req!$E$2:$E$68,"متأخر جدا")) -> 0 | G22: =IF($B22="","",IF(COUNTIFS(Link_Project_Req!$B$2:$B$68,$B22,Link_Project_Req!$E$2:$E$68,"متأخر جدا")>0,"متأخر جدا",IF(COUNTIFS(Link_Project_Req!$B$2:$B$68,$B22,Link_Project_Req!$E$2:$E$68,"متأخر")>0,"متأخر","غير متأخر"))) -> غير متأخر | H22: =IF($B22="","",IFERROR(VLOOKUP($B22,'متابعة المتطلبات'!$A$2:$J$47,10,FALSE),"")) -> رفع مستوى نضج تطبيق ممارسات إدارة البيانات
A23: 3 | B23: AR10 | C23: تطوير نظام إدارة الإنابة لضمان استمرارية الأعمال عند غياب الموظفين | D23: =IF($B23="","",IFERROR(VLOOKUP($B23,'متابعة المتطلبات'!$A$2:$K$47,11,FALSE),0)) -> 0 | E23: =IF($B23="","",COUNTIF(Link_Project_Req!$B$2:$B$68,$B23)) -> 0 | F23: =IF($B23="","",COUNTIFS(Link_Project_Req!$B$2:$B$68,$B23,Link_Project_Req!$E$2:$E$68,"متأخر")+COUNTIFS(Link_Project_Req!$B$2:$B$68,$B23,Link_Project_Req!$E$2:$E$68,"متأخر جدا")) -> 0 | G23: =IF($B23="","",IF(COUNTIFS(Link_Project_Req!$B$2:$B$68,$B23,Link_Project_Req!$E$2:$E$68,"متأخر جدا")>0,"متأخر جدا",IF(COUNTIFS(Link_Project_Req!$B$2:$B$68,$B23,Link_Project_Req!$E$2:$E$68,"متأخر")>0,"متأخر","غير متأخر"))) -> غير متأخر | H23: =IF($B23="","",IFERROR(VLOOKUP($B23,'متابعة المتطلبات'!$A$2:$J$47,10,FALSE),"")) -> تطوير نظام إدارة الإنابة
A24: 4 | B24: AR17 | C24: تطوير نظام متخصص للجودة يساعد في بناء وتحديث وتطوير الإجراءات المتعلقة بأعمال الجودة | D24: =IF($B24="","",IFERROR(VLOOKUP($B24,'متابعة المتطلبات'!$A$2:$K$47,11,FALSE),0)) -> 0 | E24: =IF($B24="","",COUNTIF(Link_Project_Req!$B$2:$B$68,$B24)) -> 1 | F24: =IF($B24="","",COUNTIFS(Link_Project_Req!$B$2:$B$68,$B24,Link_Project_Req!$E$2:$E$68,"متأخر")+COUNTIFS(Link_Project_Req!$B$2:$B$68,$B24,Link_Project_Req!$E$2:$E$68,"متأخر جدا")) -> 0 | G24: =IF($B24="","",IF(COUNTIFS(Link_Project_Req!$B$2:$B$68,$B24,Link_Project_Req!$E$2:$E$68,"متأخر جدا")>0,"متأخر جدا",IF(COUNTIFS(Link_Project_Req!$B$2:$B$68,$B24,Link_Project_Req!$E$2:$E$68,"متأخر")>0,"متأخر","غير متأخر"))) -> غير متأخر | H24: =IF($B24="","",IFERROR(VLOOKUP($B24,'متابعة المتطلبات'!$A$2:$J$47,10,FALSE),"")) -> تحقيق شهادات الجودة
A25: 5 | B25: AR18 | C25: تكامل النظام الجديد مع الأنظمة الحالية لضمان تدفق المعلومات وتحقيق الجودة الشاملة | D25: =IF($B25="","",IFERROR(VLOOKUP($B25,'متابعة المتطلبات'!$A$2:$K$47,11,FALSE),0)) -> 0 | E25: =IF($B25="","",COUNTIF(Link_Project_Req!$B$2:$B$68,$B25)) -> 1 | F25: =IF($B25="","",COUNTIFS(Link_Project_Req!$B$2:$B$68,$B25,Link_Project_Req!$E$2:$E$68,"متأخر")+COUNTIFS(Link_Project_Req!$B$2:$B$68,$B25,Link_Project_Req!$E$2:$E$68,"متأخر جدا")) -> 0 | G25: =IF($B25="","",IF(COUNTIFS(Link_Project_Req!$B$2:$B$68,$B25,Link_Project_Req!$E$2:$E$68,"متأخر جدا")>0,"متأخر جدا",IF(COUNTIFS(Link_Project_Req!$B$2:$B$68,$B25,Link_Project_Req!$E$2:$E$68,"متأخر")>0,"متأخر","غير متأخر"))) -> غير متأخر | H25: =IF($B25="","",IFERROR(VLOOKUP($B25,'متابعة المتطلبات'!$A$2:$J$47,10,FALSE),"")) -> الخدمات الاستشارية المدارة لتعزيز إدارة دورة حياة البرمجيات
A26: 6 | B26: BR15 | C26: إعداد وتنفيذ سياسة واضحة لتقييم أداء الموظف تشمل ربط المهام المنجزة بمؤشرات الأداء الرئيسية (KPIs) | D26: =IF($B26="","",IFERROR(VLOOKUP($B26,'متابعة المتطلبات'!$A$2:$K$47,11,FALSE),0)) -> 0 | E26: =IF($B26="","",COUNTIF(Link_Project_Req!$B$2:$B$68,$B26)) -> 0 | F26: =IF($B26="","",COUNTIFS(Link_Project_Req!$B$2:$B$68,$B26,Link_Project_Req!$E$2:$E$68,"متأخر")+COUNTIFS(Link_Project_Req!$B$2:$B$68,$B26,Link_Project_Req!$E$2:$E$68,"متأخر جدا")) -> 0 | G26: =IF($B26="","",IF(COUNTIFS(Link_Project_Req!$B$2:$B$68,$B26,Link_Project_Req!$E$2:$E$68,"متأخر جدا")>0,"متأخر جدا",IF(COUNTIFS(Link_Project_Req!$B$2:$B$68,$B26,Link_Project_Req!$E$2:$E$68,"متأخر")>0,"متأخر","غير متأخر"))) -> غير متأخر | H26: =IF($B26="","",IFERROR(VLOOKUP($B26,'متابعة المتطلبات'!$A$2:$J$47,10,FALSE),"")) -> توفير نظام مركزي لمتابعة الأداء وتحليل البيانات
A27: 7 | B27: DR01 | C27: وضع معايير موحدة لجودة البيانات وتقديم تدريبات للموظفين لتحسين جودة البيانات والتقارير | D27: =IF($B27="","",IFERROR(VLOOKUP($B27,'متابعة المتطلبات'!$A$2:$K$47,11,FALSE),0)) -> 0 | E27: =IF($B27="","",COUNTIF(Link_Project_Req!$B$2:$B$68,$B27)) -> 1 | F27: =IF($B27="","",COUNTIFS(Link_Project_Req!$B$2:$B$68,$B27,Link_Project_Req!$E$2:$E$68,"متأخر")+COUNTIFS(Link_Project_Req!$B$2:$B$68,$B27,Link_Project_Req!$E$2:$E$68,"متأخر جدا")) -> 0 | G27: =IF($B27="","",IF(COUNTIFS(Link_Project_Req!$B$2:$B$68,$B27,Link_Project_Req!$E$2:$E$68,"متأخر جدا")>0,"متأخر جدا",IF(COUNTIFS(Link_Project_Req!$B$2:$B$68,$B27,Link_Project_Req!$E$2:$E$68,"متأخر")>0,"متأخر","غير متأخر"))) -> غير متأخر | H27: =IF($B27="","",IFERROR(VLOOKUP($B27,'متابعة المتطلبات'!$A$2:$J$47,10,FALSE),"")) -> رفع مستوى نضج تطبيق ممارسات إدارة البيانات
A28: 8 | B28: BR04 | C28: تطوير وتطبيق نموذج متعدد القنوات لدمج جميع قنوات التواصل مع المستفيدين لتحقيق تجربة مستفيدين سلسة | D28: =IF($B28="","",IFERROR(VLOOKUP($B28,'متابعة المتطلبات'!$A$2:$K$47,11,FALSE),0)) -> 0.1 | E28: =IF($B28="","",COUNTIF(Link_Project_Req!$B$2:$B$68,$B28)) -> 2 | F28: =IF($B28="","",COUNTIFS(Link_Project_Req!$B$2:$B$68,$B28,Link_Project_Req!$E$2:$E$68,"متأخر")+COUNTIFS(Link_Project_Req!$B$2:$B$68,$B28,Link_Project_Req!$E$2:$E$68,"متأخر جدا")) -> 0 | G28: =IF($B28="","",IF(COUNTIFS(Link_Project_Req!$B$2:$B$68,$B28,Link_Project_Req!$E$2:$E$68,"متأخر جدا")>0,"متأخر جدا",IF(COUNTIFS(Link_Project_Req!$B$2:$B$68,$B28,Link_Project_Req!$E$2:$E$68,"متأخر")>0,"متأخر","غير متأخر"))) -> غير متأخر | H28: =IF($B28="","",IFERROR(VLOOKUP($B28,'متابعة المتطلبات'!$A$2:$J$47,10,FALSE),"")) -> المساعد الرقمي للعناية بالمستفيدين | المنصة الرقمية لمؤسسات التعليم والتدريب
A29: 9 | B29: BR16 | C29: إنشاء آلية فعالة لمعالجة ومتابعة المقترحات والشكاوى لضمان استجابة سريعة وفعالة | D29: =IF($B29="","",IFERROR(VLOOKUP($B29,'متابعة المتطلبات'!$A$2:$K$47,11,FALSE),0)) -> 0.1 | E29: =IF($B29="","",COUNTIF(Link_Project_Req!$B$2:$B$68,$B29)) -> 2 | F29: =IF($B29="","",COUNTIFS(Link_Project_Req!$B$2:$B$68,$B29,Link_Project_Req!$E$2:$E$68,"متأخر")+COUNTIFS(Link_Project_Req!$B$2:$B$68,$B29,Link_Project_Req!$E$2:$E$68,"متأخر جدا")) -> 0 | G29: =IF($B29="","",IF(COUNTIFS(Link_Project_Req!$B$2:$B$68,$B29,Link_Project_Req!$E$2:$E$68,"متأخر جدا")>0,"متأخر جدا",IF(COUNTIFS(Link_Project_Req!$B$2:$B$68,$B29,Link_Project_Req!$E$2:$E$68,"متأخر")>0,"متأخر","غير متأخر"))) -> غير متأخر | H29: =IF($B29="","",IFERROR(VLOOKUP($B29,'متابعة المتطلبات'!$A$2:$J$47,10,FALSE),"")) -> المساعد الرقمي للعناية بالمستفيدين | المنصة الرقمية لمؤسسات التعليم والتدريب
A30: 10 | B30: AR09 | C30: تنفيذ برامج وأدوات لقياس وتحليل رضا المستفيدين وثقتهم بشكل دوري وتحسين الأداء بناء على النتائج (داخلي وخارجي + استطلاعات رأي دورية) | D30: =IF($B30="","",IFERROR(VLOOKUP($B30,'متابعة المتطلبات'!$A$2:$K$47,11,FALSE),0)) -> 0.125 | E30: =IF($B30="","",COUNTIF(Link_Project_Req!$B$2:$B$68,$B30)) -> 2 | F30: =IF($B30="","",COUNTIFS(Link_Project_Req!$B$2:$B$68,$B30,Link_Project_Req!$E$2:$E$68,"متأخر")+COUNTIFS(Link_Project_Req!$B$2:$B$68,$B30,Link_Project_Req!$E$2:$E$68,"متأخر جدا")) -> 0 | G30: =IF($B30="","",IF(COUNTIFS(Link_Project_Req!$B$2:$B$68,$B30,Link_Project_Req!$E$2:$E$68,"متأخر جدا")>0,"متأخر جدا",IF(COUNTIFS(Link_Project_Req!$B$2:$B$68,$B30,Link_Project_Req!$E$2:$E$68,"متأخر")>0,"متأخر","غير متأخر"))) -> غير متأخر | H30: =IF($B30="","",IFERROR(VLOOKUP($B30,'متابعة المتطلبات'!$A$2:$J$47,10,FALSE),"")) -> المساعد الرقمي للعناية بالمستفيدين | توفير أداة لإنشاء الاستبيانات والتقييم جاهزة للتطبيق
A32: المشاريع المؤثرة على أكبر عدد متطلبات/فجوات
A33: # | B33: اسم المشروع | C33: حالة التنفيذ | D33: نسبة الإنجاز % | E33: #الفجوات | F33: #المتطلبات | G33: إجمالي التأثير | H33: اختصار الفجوات | I33: اختصار المتطلبات
A34: 1 | B34: تأسيس وتنفيذ وتشغيل البنية المؤسسية في هيئة تقويم التعليم و التدريب | C34: =IF($B34="","",IFERROR(VLOOKUP($B34,'متابعة المشاريع'!$A$2:$E$1003,5,FALSE),"")) -> قيد التنفيذ | D34: =IF($B34="","",IFERROR(VLOOKUP($B34,'متابعة المشاريع'!$A$2:$F$1003,6,FALSE),0)) -> 0.75 | E34: =IF($B34="","",IFERROR(VLOOKUP($B34,'متابعة المشاريع'!$A$2:$L$1003,12,FALSE),0)) -> 17 | F34: =IF($B34="","",IFERROR(VLOOKUP($B34,'متابعة المشاريع'!$A$2:$K$1003,11,FALSE),0)) -> 10 | G34: =IF($B34="","",$E34+$F34) -> 27 | H34: =IF($B34="","",IFERROR(VLOOKUP($B34,'متابعة المشاريع'!$A$2:$C$1003,3,FALSE),"")) -> GAP-A-04 | GAP-A-05 | GAP-B-02 | GAP-B-06 | GAP-B-10 | GAP-B-13 | GAP-B-15 | GAP-B-19 | GAP-B-22 | GAP-B-26 | GAP-B-28 | GAP-B-29 | GAP-B-78 | GAP-B-84 | GAP-B-87 | GAP-B-88 | GAP-B-90 | I34: =IF($B34="","",IFERROR(VLOOKUP($B34,'متابعة المشاريع'!$A$2:$D$1003,4,FALSE),"")) -> BR01 | BR08 | BR09 | BR10 | BR11 | BR13 | BR14 | BR17 | BR18 | BR20
A35: 2 | B35: المنصة الرقمية لمؤسسات التعليم والتدريب | C35: =IF($B35="","",IFERROR(VLOOKUP($B35,'متابعة المشاريع'!$A$2:$E$1003,5,FALSE),"")) -> حسب المخطط | D35: =IF($B35="","",IFERROR(VLOOKUP($B35,'متابعة المشاريع'!$A$2:$F$1003,6,FALSE),0)) -> 0.2 | E35: =IF($B35="","",IFERROR(VLOOKUP($B35,'متابعة المشاريع'!$A$2:$L$1003,12,FALSE),0)) -> 15 | F35: =IF($B35="","",IFERROR(VLOOKUP($B35,'متابعة المشاريع'!$A$2:$K$1003,11,FALSE),0)) -> 9 | G35: =IF($B35="","",$E35+$F35) -> 24 | H35: =IF($B35="","",IFERROR(VLOOKUP($B35,'متابعة المشاريع'!$A$2:$C$1003,3,FALSE),"")) -> GAP-A-04 | GAP-A-05 | GAP-B-04 | GAP-B-05 | GAP-B-16 | GAP-B-17 | GAP-B-20 | GAP-B-23 | GAP-B-24 | GAP-B-25 | GAP-B-86 | GAP-B-89 | GAP-D-10 | GAP-D-11 | GAP-D-31 | I35: =IF($B35="","",IFERROR(VLOOKUP($B35,'متابعة المشاريع'!$A$2:$D$1003,4,FALSE),"")) -> AR06 | AR14 | AR15 | AR16 | BR03 | BR04 | BR10 | BR16 | BR19
A36: 3 | B36: تحقيق شهادات الجودة | C36: =IF($B36="","",IFERROR(VLOOKUP($B36,'متابعة المشاريع'!$A$2:$E$1003,5,FALSE),"")) -> لم يبدأ | D36: =IF($B36="","",IFERROR(VLOOKUP($B36,'متابعة المشاريع'!$A$2:$F$1003,6,FALSE),0)) -> 0 | E36: =IF($B36="","",IFERROR(VLOOKUP($B36,'متابعة المشاريع'!$A$2:$L$1003,12,FALSE),0)) -> 11 | F36: =IF($B36="","",IFERROR(VLOOKUP($B36,'متابعة المشاريع'!$A$2:$K$1003,11,FALSE),0)) -> 8 | G36: =IF($B36="","",$E36+$F36) -> 19 | H36: =IF($B36="","",IFERROR(VLOOKUP($B36,'متابعة المشاريع'!$A$2:$C$1003,3,FALSE),"")) -> GAP-B-02 | GAP-B-06 | GAP-B-13 | GAP-B-14 | GAP-B-15 | GAP-B-29 | GAP-B-67 | GAP-B-75 | GAP-B-77 | GAP-B-87 | GAP-B-88 | I36: =IF($B36="","",IFERROR(VLOOKUP($B36,'متابعة المشاريع'!$A$2:$D$1003,4,FALSE),"")) -> AR17 | BR01 | BR05 | BR06 | BR07 | BR13 | BR17 | BR18
A37: 4 | B37: مشروع دعم مايكروسوفت الموحد | C37: =IF($B37="","",IFERROR(VLOOKUP($B37,'متابعة المشاريع'!$A$2:$E$1003,5,FALSE),"")) -> قيد التنفيذ | D37: =IF($B37="","",IFERROR(VLOOKUP($B37,'متابعة المشاريع'!$A$2:$F$1003,6,FALSE),0)) -> 0.7 | E37: =IF($B37="","",IFERROR(VLOOKUP($B37,'متابعة المشاريع'!$A$2:$L$1003,12,FALSE),0)) -> 7 | F37: =IF($B37="","",IFERROR(VLOOKUP($B37,'متابعة المشاريع'!$A$2:$K$1003,11,FALSE),0)) -> 6 | G37: =IF($B37="","",$E37+$F37) -> 13 | H37: =IF($B37="","",IFERROR(VLOOKUP($B37,'متابعة المشاريع'!$A$2:$C$1003,3,FALSE),"")) -> GAP-A-05 | GAP-B-14 | GAP-B-16 | GAP-B-17 | GAP-B-25 | GAP-B-75 | GAP-B-89 | I37: =IF($B37="","",IFERROR(VLOOKUP($B37,'متابعة المشاريع'!$A$2:$D$1003,4,FALSE),"")) -> AR01 | AR16 | AR19 | BR05 | BR06 | BR19
A38: 5 | B38: المساعد الرقمي للعناية بالمستفيدين | C38: =IF($B38="","",IFERROR(VLOOKUP($B38,'متابعة المشاريع'!$A$2:$E$1003,5,FALSE),"")) -> لم يبدأ | D38: =IF($B38="","",IFERROR(VLOOKUP($B38,'متابعة المشاريع'!$A$2:$F$1003,6,FALSE),0)) -> 0 | E38: =IF($B38="","",IFERROR(VLOOKUP($B38,'متابعة المشاريع'!$A$2:$L$1003,12,FALSE),0)) -> 7 | F38: =IF($B38="","",IFERROR(VLOOKUP($B38,'متابعة المشاريع'!$A$2:$K$1003,11,FALSE),0)) -> 3 | G38: =IF($B38="","",$E38+$F38) -> 10 | H38: =IF($B38="","",IFERROR(VLOOKUP($B38,'متابعة المشاريع'!$A$2:$C$1003,3,FALSE),"")) -> GAP-B-04 | GAP-B-05 | GAP-B-17 | GAP-B-20 | GAP-B-23 | GAP-B-86 | GAP-D-14 | I38: =IF($B38="","",IFERROR(VLOOKUP($B38,'متابعة المشاريع'!$A$2:$D$1003,4,FALSE),"")) -> AR09 | BR04 | BR16
A39: 6 | B39: منصة ديجيتال اكس | C39: =IF($B39="","",IFERROR(VLOOKUP($B39,'متابعة المشاريع'!$A$2:$E$1003,5,FALSE),"")) -> قيد التنفيذ | D39: =IF($B39="","",IFERROR(VLOOKUP($B39,'متابعة المشاريع'!$A$2:$F$1003,6,FALSE),0)) -> 0.45 | E39: =IF($B39="","",IFERROR(VLOOKUP($B39,'متابعة المشاريع'!$A$2:$L$1003,12,FALSE),0)) -> 6 | F39: =IF($B39="","",IFERROR(VLOOKUP($B39,'متابعة المشاريع'!$A$2:$K$1003,11,FALSE),0)) -> 3 | G39: =IF($B39="","",$E39+$F39) -> 9 | H39: =IF($B39="","",IFERROR(VLOOKUP($B39,'متابعة المشاريع'!$A$2:$C$1003,3,FALSE),"")) -> GAP-B-21 | GAP-B-28 | GAP-B-63 | GAP-B-70 | GAP-B-85 | GAP-B-90 | I39: =IF($B39="","",IFERROR(VLOOKUP($B39,'متابعة المشاريع'!$A$2:$D$1003,4,FALSE),"")) -> AR12 | AR13 | AR20
A40: 7 | B40: توريد وتركيب أدوات ذكاء الأعمال والتحليلات المتقدمة | C40: =IF($B40="","",IFERROR(VLOOKUP($B40,'متابعة المشاريع'!$A$2:$E$1003,5,FALSE),"")) -> قيد التنفيذ | D40: =IF($B40="","",IFERROR(VLOOKUP($B40,'متابعة المشاريع'!$A$2:$F$1003,6,FALSE),0)) -> 0.4 | E40: =IF($B40="","",IFERROR(VLOOKUP($B40,'متابعة المشاريع'!$A$2:$L$1003,12,FALSE),0)) -> 4 | F40: =IF($B40="","",IFERROR(VLOOKUP($B40,'متابعة المشاريع'!$A$2:$K$1003,11,FALSE),0)) -> 4 | G40: =IF($B40="","",$E40+$F40) -> 8 | H40: =IF($B40="","",IFERROR(VLOOKUP($B40,'متابعة المشاريع'!$A$2:$C$1003,3,FALSE),"")) -> GAP-B-07 | GAP-B-18 | GAP-D-13 | GAP-T-13 | I40: =IF($B40="","",IFERROR(VLOOKUP($B40,'متابعة المشاريع'!$A$2:$D$1003,4,FALSE),"")) -> AR02 | AR08 | AR11 | BR12
A41: 8 | B41: تشغيل وصيانة نظم البيانات والتكامل وذكاء الأعمال لمنافسة | C41: =IF($B41="","",IFERROR(VLOOKUP($B41,'متابعة المشاريع'!$A$2:$E$1003,5,FALSE),"")) -> قيد التنفيذ | D41: =IF($B41="","",IFERROR(VLOOKUP($B41,'متابعة المشاريع'!$A$2:$F$1003,6,FALSE),0)) -> 0.65 | E41: =IF($B41="","",IFERROR(VLOOKUP($B41,'متابعة المشاريع'!$A$2:$L$1003,12,FALSE),0)) -> 4 | F41: =IF($B41="","",IFERROR(VLOOKUP($B41,'متابعة المشاريع'!$A$2:$K$1003,11,FALSE),0)) -> 2 | G41: =IF($B41="","",$E41+$F41) -> 6 | H41: =IF($B41="","",IFERROR(VLOOKUP($B41,'متابعة المشاريع'!$A$2:$C$1003,3,FALSE),"")) -> GAP-B-18 | GAP-D-10 | GAP-D-11 | GAP-D-31 | I41: =IF($B41="","",IFERROR(VLOOKUP($B41,'متابعة المشاريع'!$A$2:$D$1003,4,FALSE),"")) -> AR02 | AR06
A42: 9 | B42: تفعيل الابتكار الرقمي | C42: =IF($B42="","",IFERROR(VLOOKUP($B42,'متابعة المشاريع'!$A$2:$E$1003,5,FALSE),"")) -> لم يبدأ | D42: =IF($B42="","",IFERROR(VLOOKUP($B42,'متابعة المشاريع'!$A$2:$F$1003,6,FALSE),0)) -> 0 | E42: =IF($B42="","",IFERROR(VLOOKUP($B42,'متابعة المشاريع'!$A$2:$L$1003,12,FALSE),0)) -> 4 | F42: =IF($B42="","",IFERROR(VLOOKUP($B42,'متابعة المشاريع'!$A$2:$K$1003,11,FALSE),0)) -> 2 | G42: =IF($B42="","",$E42+$F42) -> 6 | H42: =IF($B42="","",IFERROR(VLOOKUP($B42,'متابعة المشاريع'!$A$2:$C$1003,3,FALSE),"")) -> GAP-B-14 | GAP-B-19 | GAP-B-77 | GAP-B-78 | I42: =IF($B42="","",IFERROR(VLOOKUP($B42,'متابعة المشاريع'!$A$2:$D$1003,4,FALSE),"")) -> BR07 | BR08
A43: 10 | B43: توريد وتركيب أدوات إدارة البيانات الوصفية والبيانات الرئيسية والمرجعية | C43: =IF($B43="","",IFERROR(VLOOKUP($B43,'متابعة المشاريع'!$A$2:$E$1003,5,FALSE),"")) -> قيد التنفيذ | D43: =IF($B43="","",IFERROR(VLOOKUP($B43,'متابعة المشاريع'!$A$2:$F$1003,6,FALSE),0)) -> 0.4 | E43: =IF($B43="","",IFERROR(VLOOKUP($B43,'متابعة المشاريع'!$A$2:$L$1003,12,FALSE),0)) -> 4 | F43: =IF($B43="","",IFERROR(VLOOKUP($B43,'متابعة المشاريع'!$A$2:$K$1003,11,FALSE),0)) -> 2 | G43: =IF($B43="","",$E43+$F43) -> 6 | H43: =IF($B43="","",IFERROR(VLOOKUP($B43,'متابعة المشاريع'!$A$2:$C$1003,3,FALSE),"")) -> GAP-D-06 | GAP-D-16 | GAP-D-28 | GAP-T-7 | I43: =IF($B43="","",IFERROR(VLOOKUP($B43,'متابعة المشاريع'!$A$2:$D$1003,4,FALSE),"")) -> AR04 | DR02
A44: 11 | B44: رفع مستوى نضج تطبيق ممارسات إدارة البيانات | C44: =IF($B44="","",IFERROR(VLOOKUP($B44,'متابعة المشاريع'!$A$2:$E$1003,5,FALSE),"")) -> لم يبدأ | D44: =IF($B44="","",IFERROR(VLOOKUP($B44,'متابعة المشاريع'!$A$2:$F$1003,6,FALSE),0)) -> 0 | E44: =IF($B44="","",IFERROR(VLOOKUP($B44,'متابعة المشاريع'!$A$2:$L$1003,12,FALSE),0)) -> 4 | F44: =IF($B44="","",IFERROR(VLOOKUP($B44,'متابعة المشاريع'!$A$2:$K$1003,11,FALSE),0)) -> 2 | G44: =IF($B44="","",$E44+$F44) -> 6 | H44: =IF($B44="","",IFERROR(VLOOKUP($B44,'متابعة المشاريع'!$A$2:$C$1003,3,FALSE),"")) -> GAP-D-07 | GAP-D-09 | GAP-D-15 | GAP-T-8 | I44: =IF($B44="","",IFERROR(VLOOKUP($B44,'متابعة المشاريع'!$A$2:$D$1003,4,FALSE),"")) -> AR05 | DR01
...

Sheet تعريف
A1: تعريف متطلبات البنية المؤسسية
A3: متطلبات البنية المؤسسية هي احتياجات/التزامات قابلة للقياس تُعرِّف ما يجب على الهيئة تحقيقه أو توفيره ضمن مجالات البنية (الأعمال، البيانات، التطبيقات، التقنية/الأمن) لضمان المواءمة الاستراتيجية، الحوكمة، وتحسين الكفاءة وتجربة المستفيد.
A5: طريقة استخدام السجل
A6: 1) راجع شيت (سجل المتطلبات)؛ نصوص المتطلبات كما هي بدون إعادة صياغة.
A7: 2) لكل متطلب: اربطه بالفجوات (أكواد GAP-*) وبالمشاريع المناسبة من شيت (المشاريع).
A8: 3) عبّئ (مدى الصعوبة، حالة التنفيذ، الأدلة) من واقع التنفيذ فقط.
A9: 4) استخدم شيت (الفجوات) لتتبع إغلاق الفجوات وربطها بالمتطلبات والمشاريع.

Sheet قوائم
A1: المجالات | B1: الأولوية | C1: حالة المتطلب/التنفيذ | D1: مدى الصعوبة | E1: حالة الدليل | F1: نوع الدليل | G1: أهداف البنية المؤسسية | H1: أكواد الفجوات | I1: المشاريع | J1: حالة المشروع | K1: مصادر المتطلبات
A2: الأعمال | B2: عالي | C2: جديد | D2: منخفض | E2: غير متوفر | F2: وثيقة | G2: دعم اتخاذ القرارات | H2: GAP-B-01 | I2: توفير أداة لإنشاء الاستبيانات والتقييم جاهزة للتطبيق | J2: لم يبدأ | K2: أخصائي الجودة للأعمال
A3: البيانات | B3: متدني | C3: لم يبدأ | D3: متوسط | E3: جزئي | F3: تقرير | G3: تعزيز الكفاءة التشغيلية وكفاءة الانفاق | H3: GAP-B-02 | I3: مشروع دعم مايكروسوفت الموحد | J3: قيد التنفيذ | K3: إدارة التميز المؤسسي
A4: التقنية | B4: متوسط | C4: جاري | D4: مرتفع | E4: متوفر | F4: محضر/عرض | G4: تمكين التحول الرقمي | H4: GAP-B-03 | I4: توريد وتركيب وترقية أجهزة موزع الأحمال والرخص الخاصة بها | J4: مكتمل | K4: التحليل الرباعي
B5: مرتفع | C5: مكتمل | F5: لقطة شاشة | G5: دعم تحسين تجربة المستفيد | H5: GAP-B-04 | I5: توريد أجهزة الجدار الناري والرخص الخاصة بها | J5: متعثر | K5: تقييم القدرات المؤسسية
C6: متعثر | F6: سجل نظام | G6: تعزيز الحوكمة المؤسسية | H6: GAP-B-05 | I6: تطبيق خدمة النفاذ الوطني الموحد في هيئة تقويم التعليم والتدريب | J6: مؤجل
C7: مؤجل | F7: بريد إلكتروني | G7: المواءمة الاستراتيجية | H7: GAP-B-06 | I7: تقديم خدمة أداء الاختبارات الرقمية للرجال بمحافظة جدة
F8: رابط نظام/بوابة | H8: GAP-B-07 | I8: توفير نظام لتطبيق الاختبارات الطارئة لهيئة تقويم التعليم والتدريب
F9: أخرى | H9: GAP-B-08 | I9: توريد وتركيب أجهزة حفظ الطاقة بمقرات الاختبارات المحوسبة وتقديم الدعم الفني
H10: GAP-B-09 | I10: توفير خدمة للتعلم الإلكتروني جاهزة للاستخدام
H11: GAP-B-10 | I11: تأمين خدمة التحقق من بيانات المتقدمين للاختبارات يقين
H12: GAP-B-11 | I12: مشروع البنية التحتية لنظام سطح المكتب الافتراضي VDI
H13: GAP-B-12 | I13: الربط الشبكي لمقرات الاختبارات المحوسبة
H14: GAP-B-13 | I14: مشروع شراء وتجديد رخص البرامج في هيئة تقويم التعليم والتدريب
H15: GAP-B-14 | I15: تجديد رخص أنظمة
H16: GAP-B-15 | I16: تأمين خدمة الرسائل النصية لهيئة تقويم التعليم والتدريب
H17: GAP-B-16 | I17: توفير وتركيب أداة التطوير منخفضة صفرية الترميز
H18: GAP-B-17 | I18: صيانة وتطوير تطبيق التحقق من هوية المختبرين
H19: GAP-B-18 | I19: تقديم خدمة أداء الاختبارات الرقمية في المدن التالية: غرب مدينة الرياض - الدمام - المدينة المنورة - الطائف - بريدة - الهفوف - جازان - جدة
H20: GAP-B-19 | I20: الدعم الفني لأنظمة إدارة الموارد ساب
H21: GAP-B-20 | I21: تطوير نظامي إدارة استكشاف الأصول التقنية والأجهزة الطرفية
... H69: GAP-A-06 | I69: تقديم خدمة أداء الاختبارات الرقمية في المدن التالية: المقرات النموذجي
H70: GAP-A-07
H71: GAP-A-08
H72: GAP-A-09
H73: GAP-A-10
H74: GAP-T-1
H75: GAP-T-2
H76: GAP-T-3
H77: GAP-T-4
H78: GAP-T-5
H79: GAP-T-6
H80: GAP-T-7
H81: GAP-T-8
... H93: GAP-T-20

Sheet متابعة المشاريع
A1: اسم المشروع | B1: طبقة/مجال المشروع (اختياري) | C1: الفجوات المستهدفة (GAP-*) | D1: المتطلبات التي يحققها (BR/AR/DR/TR) | E1: حالة التنفيذ | F1: نسبة الإنجاز % | G1: تاريخ البدء | H1: تاريخ الانتهاء | I1: المالك | J1: ملاحظات | K1: عدد المتطلبات المرتبطة | L1: عدد الفجوات المرتبطة | M1: نسبة إنجاز المشروع (مؤكدة)
A2: توفير أداة لإنشاء الاستبيانات والتقييم جاهزة للتطبيق | B2: الأعمال | C2: GAP-B-20 | GAP-D-14 | D2: AR09 | E2: قيد التنفيذ | F2: 0.25 | G2: 45931 | H2: 46142 | I2: إدارة التميز المؤسسي | K2: =COUNTIF(Link_Project_Req!$A$2:$A$68,$A2) -> 1 | L2: =COUNTIF(Link_Project_Gap!$A$2:$A$112,$A2) -> 2 | M2: =IF($F2="",0,$F2) -> 0.25
A3: مشروع دعم مايكروسوفت الموحد | B3: الأعمال | C3: GAP-A-05 | GAP-B-14 | GAP-B-16 | GAP-B-17 | GAP-B-25 | GAP-B-75 | GAP-B-89 | D3: AR01 | AR16 | AR19 | BR05 | BR06 | BR19 | E3: قيد التنفيذ | F3: 0.7 | G3: 45658 | H3: 46387 | I3: إدارة التميز المؤسسي | K3: =COUNTIF(Link_Project_Req!$A$2:$A$68,$A3) -> 6 | L3: =COUNTIF(Link_Project_Gap!$A$2:$A$112,$A3) -> 7 | M3: =IF($F3="",0,$F3) -> 0.7
A4: توريد وتركيب وترقية أجهزة موزع الأحمال والرخص الخاصة بها | E4: قيد التنفيذ | F4: 0.4 | G4: 45901 | H4: 46203 | I4: الإدارة العامة لتقنية المعلومات | K4: =COUNTIF(Link_Project_Req!$A$2:$A$68,$A4) -> 0 | L4: =COUNTIF(Link_Project_Gap!$A$2:$A$112,$A4) -> 0 | M4: =IF($F4="",0,$F4) -> 0.4
A5: توريد أجهزة الجدار الناري والرخص الخاصة بها | E5: قيد التنفيذ | F5: 0.4 | G5: 45901 | H5: 46203 | I5: الإدارة العامة لتقنية المعلومات | K5: =COUNTIF(Link_Project_Req!$A$2:$A$68,$A5) -> 0 | L5: =COUNTIF(Link_Project_Gap!$A$2:$A$112,$A5) -> 0 | M5: =IF($F5="",0,$F5) -> 0.4
A6: تطبيق خدمة النفاذ الوطني الموحد في هيئة تقويم التعليم والتدريب | B6: التقنية | C6: GAP-T-10 | D6: TR01 | E6: قيد التنفيذ | F6: 0.55 | G6: 45839 | H6: 46112 | I6: البنية التحتية والأمن السيبراني | K6: =COUNTIF(Link_Project_Req!$A$2:$A$68,$A6) -> 1 | L6: =COUNTIF(Link_Project_Gap!$A$2:$A$112,$A6) -> 1 | M6: =IF($F6="",0,$F6) -> 0.55
A7: تقديم خدمة أداء الاختبارات الرقمية للرجال بمحافظة جدة | E7: قيد التنفيذ | F7: 0.8 | G7: 45809 | H7: 46387 | I7: الإدارة العامة لتقنية المعلومات | K7: =COUNTIF(Link_Project_Req!$A$2:$A$68,$A7) -> 0 | L7: =COUNTIF(Link_Project_Gap!$A$2:$A$112,$A7) -> 0 | M7: =IF($F7="",0,$F7) -> 0.8
A8: توفير نظام لتطبيق الاختبارات الطارئة لهيئة تقويم التعليم والتدريب | E8: قيد التنفيذ | F8: 0.25 | G8: 45931 | H8: 46142 | I8: الإدارة العامة لتقنية المعلومات | K8: =COUNTIF(Link_Project_Req!$A$2:$A$68,$A8) -> 0 | L8: =COUNTIF(Link_Project_Gap!$A$2:$A$112,$A8) -> 0 | M8: =IF($F8="",0,$F8) -> 0.25
A9: توريد وتركيب أجهزة حفظ الطاقة بمقرات الاختبارات المحوسبة وتقديم الدعم الفني | B9: التقنية | C9: GAP-T-14 | GAP-T-17 | D9: TR04 | E9: قيد التنفيذ | F9: 0.4 | G9: 45901 | H9: 46203 | I9: البنية التحتية والأمن السيبراني | K9: =COUNTIF(Link_Project_Req!$A$2:$A$68,$A9) -> 1 | L9: =COUNTIF(Link_Project_Gap!$A$2:$A$112,$A9) -> 2 | M9: =IF($F9="",0,$F9) -> 0.4
A10: توفير خدمة للتعلم الإلكتروني جاهزة للاستخدام | E10: قيد التنفيذ | F10: 0.25 | G10: 45931 | H10: 46142 | I10: الإدارة العامة لتقنية المعلومات | K10: =COUNTIF(Link_Project_Req!$A$2:$A$68,$A10) -> 0 | L10: =COUNTIF(Link_Project_Gap!$A$2:$A$112,$A10) -> 0 | M10: =IF($F10="",0,$F10) -> 0.25
A11: تأمين خدمة التحقق من بيانات المتقدمين للاختبارات يقين | E11: قيد التنفيذ | F11: 0.25 | G11: 45931 | H11: 46142 | I11: الإدارة العامة لتقنية المعلومات | K11: =COUNTIF(Link_Project_Req!$A$2:$A$68,$A11) -> 0 | L11: =COUNTIF(Link_Project_Gap!$A$2:$A$112,$A11) -> 0 | M11: =IF($F11="",0,$F11) -> 0.25
A12: مشروع البنية التحتية لنظام سطح المكتب الافتراضي VDI | E12: لم يبدأ | F12: 0 | G12: 46023 | H12: 46387 | I12: الإدارة العامة لتقنية المعلومات | K12: =COUNTIF(Link_Project_Req!$A$2:$A$68,$A12) -> 0 | L12: =COUNTIF(Link_Project_Gap!$A$2:$A$112,$A12) -> 0 | M12: =IF($F12="",0,$F12) -> 0
A13: الربط الشبكي لمقرات الاختبارات المحوسبة | B13: التقنية | C13: GAP-T-11 | GAP-T-14 | D13: TR02 | E13: لم يبدأ | F13: 0 | G13: 46023 | H13: 46387 | I13: البنية التحتية والأمن السيبراني | K13: =COUNTIF(Link_Project_Req!$A$2:$A$68,$A13) -> 1 | L13: =COUNTIF(Link_Project_Gap!$A$2:$A$112,$A13) -> 2 | M13: =IF($F13="",0,$F13) -> 0
A14: مشروع شراء وتجديد رخص البرامج في هيئة تقويم التعليم والتدريب | E14: مكتمل | F14: 1 | G14: 45962 | H14: 46022 | I14: الإدارة العامة لتقنية المعلومات | K14: =COUNTIF(Link_Project_Req!$A$2:$A$68,$A14) -> 0 | L14: =COUNTIF(Link_Project_Gap!$A$2:$A$112,$A14) -> 0 | M14: =IF($F14="",0,$F14) -> 1
A15: تجديد رخص أنظمة | E15: مكتمل | F15: 1 | G15: 45962 | H15: 46022 | I15: الإدارة العامة لتقنية المعلومات | K15: =COUNTIF(Link_Project_Req!$A$2:$A$68,$A15) -> 0 | L15: =COUNTIF(Link_Project_Gap!$A$2:$A$112,$A15) -> 0 | M15: =IF($F15="",0,$F15) -> 1
A16: تأمين خدمة الرسائل النصية لهيئة تقويم التعليم والتدريب | E16: قيد التنفيذ | F16: 0.25 | G16: 45931 | H16: 46142 | I16: الإدارة العامة لتقنية المعلومات | K16: =COUNTIF(Link_Project_Req!$A$2:$A$68,$A16) -> 0 | L16: =COUNTIF(Link_Project_Gap!$A$2:$A$112,$A16) -> 0 | M16: =IF($F16="",0,$F16) -> 0.25
A17: توفير وتركيب أداة التطوير منخفضة صفرية الترميز | E17: قيد التنفيذ | F17: 0.25 | G17: 45931 | H17: 46142 | I17: الإدارة العامة لتقنية المعلومات | K17: =COUNTIF(Link_Project_Req!$A$2:$A$68,$A17) -> 0 | L17: =COUNTIF(Link_Project_Gap!$A$2:$A$112,$A17) -> 0 | M17: =IF($F17="",0,$F17) -> 0.25
A18: صيانة وتطوير تطبيق التحقق من هوية المختبرين | E18: قيد التنفيذ | F18: 0.35 | G18: 45931 | H18: 46295 | I18: الإدارة العامة لتقنية المعلومات | K18: =COUNTIF(Link_Project_Req!$A$2:$A$68,$A18) -> 0 | L18: =COUNTIF(Link_Project_Gap!$A$2:$A$112,$A18) -> 0 | M18: =IF($F18="",0,$F18) -> 0.35
A19: تقديم خدمة أداء الاختبارات الرقمية في المدن التالية: غرب مدينة الرياض - الدمام - المدينة المنورة - الطائف - بريدة - الهفوف - جازان - جدة | E19: قيد التنفيذ | F19: 0.8 | G19: 45809 | H19: 46387 | I19: الإدارة العامة لتقنية المعلومات | K19: =COUNTIF(Link_Project_Req!$A$2:$A$68,$A19) -> 0 | L19: =COUNTIF(Link_Project_Gap!$A$2:$A$112,$A19) -> 0 | M19: =IF($F19="",0,$F19) -> 0.8
A20: الدعم الفني لأنظمة إدارة الموارد ساب | E20: حسب المخطط | F20: 0.25 | G20: 1 | H20: 45852 | I20: 46583 | K20: =COUNTIF(Link_Project_Req!$A$2:$A$68,$A20) -> 0 | L20: =COUNTIF(Link_Project_Gap!$A$2:$A$112,$A20) -> 0 | M20: =IF($F20="",0,$F20) -> 0.25
A21: تطوير نظامي إدارة استكشاف الأصول التقنية والأجهزة الطرفية | B21: التقنية | C21: GAP-A-06 | GAP-D-12 | GAP-T-4 | D21: AR07 | E21: حسب المخطط | F21: 0.45 | G21: 0.45 | H21: 45946 | I21: 47042 | K21: =COUNTIF(Link_Project_Req!$A$2:$A$68,$A21) -> 1 | L21: =COUNTIF(Link_Project_Gap!$A$2:$A$112,$A21) -> 3 | M21: =IF($F21="",0,$F21) -> 0.45
A22: استضافة مركز البيانات | E22: لم يبدأ | F22: 0 | G22: 46023 | H22: 46387 | I22: الإدارة العامة لتقنية المعلومات | K22: =COUNTIF(Link_Project_Req!$A$2:$A$68,$A22) -> 0 | L22: =COUNTIF(Link_Project_Gap!$A$2:$A$112,$A22) -> 0 | M22: =IF($F22="",0,$F22) -> 0
A23: منافسة تقديم خدمات لأنظمة تطبيق الاختبارات المحوسبة | E23: لم يبدأ | F23: 0 | G23: 46023 | H23: 46387 | I23: الإدارة العامة لتقنية المعلومات | K23: =COUNTIF(Link_Project_Req!$A$2:$A$68,$A23) -> 0 | L23: =COUNTIF(Link_Project_Gap!$A$2:$A$112,$A23) -> 0 | M23: =IF($F23="",0,$F23) -> 0
A24: تطوير نظامي اختبارات الطوارئ والاختبارات المؤسسية | B24: الأعمال | C24: GAP-A-07 | GAP-B-01 | D24: BR02 | E24: قيد التنفيذ | F24: 0.35 | G24: 45931 | H24: 46295 | I24: إدارة التميز المؤسسي | K24: =COUNTIF(Link_Project_Req!$A$2:$A$68,$A24) -> 1 | L24: =COUNTIF(Link_Project_Gap!$A$2:$A$112,$A24) -> 2 | M24: =IF($F24="",0,$F24) -> 0.35
A25: تطوير تطبيق ومنصة مستقبلهم | E25: حسب المخطط | F25: 0 | G25: 0 | H25: 46022 | I25: 46752 | K25: =COUNTIF(Link_Project_Req!$A$2:$A$68,$A25) -> 0 | L25: =COUNTIF(Link_Project_Gap!$A$2:$A$112,$A25) -> 0 | M25: =IF($F25="",0,$F25) -> 0
A26: التصحيح الالي | E26: لم يبدأ | F26: 0 | G26: 46023 | H26: 46387 | I26: الإدارة العامة لتقنية المعلومات | K26: =COUNTIF(Link_Project_Req!$A$2:$A$68,$A26) -> 0 | L26: =COUNTIF(Link_Project_Gap!$A$2:$A$112,$A26) -> 0 | M26: =IF($F26="",0,$F26) -> 0
A27: توريد وتركيب وتشغيل الكبائن الذكية لتطبيق الاختبارات | E27: قيد التنفيذ | F27: 0.4 | G27: 45901 | H27: 46203 | I27: الإدارة العامة لتقنية المعلومات | K27: =COUNTIF(Link_Project_Req!$A$2:$A$68,$A27) -> 0 | L27: =COUNTIF(Link_Project_Gap!$A$2:$A$112,$A27) -> 0 | M27: =IF($F27="",0,$F27) -> 0.4
A28: تفعيل الابتكار الرقمي | B28: الأعمال | C28: GAP-B-14 | GAP-B-19 | GAP-B-77 | GAP-B-78 | D28: BR07 | BR08 | E28: لم يبدأ | F28: 0 | G28: 46023 | H28: 46387 | I28: إدارة التميز المؤسسي | K28: =COUNTIF(Link_Project_Req!$A$2:$A$68,$A28) -> 2 | L28: =COUNTIF(Link_Project_Gap!$A$2:$A$112,$A28) -> 4 | M28: =IF($F28="",0,$F28) -> 0
A29: توريد وتركيب أدوات إدارة البيانات الوصفية والبيانات الرئيسية والمرجعية | B29: البيانات | C29: GAP-D-06 | GAP-D-16 | GAP-D-28 | GAP-T-7 | D29: AR04 | DR02 | E29: قيد التنفيذ | F29: 0.4 | G29: 45901 | H29: 46203 | I29: إدارة البيانات | K29: =COUNTIF(Link_Project_Req!$A$2:$A$68,$A29) -> 2 | L29: =COUNTIF(Link_Project_Gap!$A$2:$A$112,$A29) -> 4 | M29: =IF($F29="",0,$F29) -> 0.4
A30: توريد وتركيب أدوات ذكاء الأعمال والتحليلات المتقدمة | B30: الأعمال | C30: GAP-B-07 | GAP-B-18 | GAP-D-13 | GAP-T-13 | D30: AR02 | AR08 | AR11 | BR12 | E30: قيد التنفيذ | F30: 0.4 | G30: 45901 | H30: 46203 | I30: إدارة التميز المؤسسي | K30: =COUNTIF(Link_Project_Req!$A$2:$A$68,$A30) -> 4 | L30: =COUNTIF(Link_Project_Gap!$A$2:$A$112,$A30) -> 4 | M30: =IF($F30="",0,$F30) -> 0.4
A31: رفع مستوى نضج تطبيق ممارسات إدارة البيانات | B31: البيانات | C31: GAP-D-07 | GAP-D-09 | GAP-D-15 | GAP-T-8 | D31: AR05 | DR01 | E31: لم يبدأ | F31: 0 | G31: 46023 | H31: 46387 | I31: إدارة البيانات | K31: =COUNTIF(Link_Project_Req!$A$2:$A$68,$A31) -> 2 | L31: =COUNTIF(Link_Project_Gap!$A$2:$A$112,$A31) -> 4 | M31: =IF($F31="",0,$F31) -> 0
A32: المساعد الرقمي للعناية بالمستفيدين | B32: الأعمال | C32: GAP-B-04 | GAP-B-05 | GAP-B-17 | GAP-B-20 | GAP-B-23 | GAP-B-86 | GAP-D-14 | D32: AR09 | BR04 | BR16 | E32: لم يبدأ | F32: 0 | G32: 46023 | H32: 46387 | I32: إدارة التميز المؤسسي | K32: =COUNTIF(Link_Project_Req!$A$2:$A$68,$A32) -> 3 | L32: =COUNTIF(Link_Project_Gap!$A$2:$A$112,$A32) -> 7 | M32: =IF($F32="",0,$F32) -> 0
A33: استمرارية الاعمال | E33: لم يبدأ | F33: 0 | G33: 46023 | H33: 46387 | I33: الإدارة العامة لتقنية المعلومات | K33: =COUNTIF(Link_Project_Req!$A$2:$A$68,$A33) -> 0 | L33: =COUNTIF(Link_Project_Gap!$A$2:$A$112,$A33) -> 0 | M33: =IF($F33="",0,$F33) -> 0
A34: تطبيقات الذكاء الاصطناعي | B34: الأعمال | C34: GAP-D-13 | GAP-T-13 | D34: AR08 | TR05 | E34: لم يبدأ | F34: 0 | G34: 46023 | H34: 46387 | I34: إدارة التميز المؤسسي | K34: =COUNTIF(Link_Project_Req!$A$2:$A$68,$A34) -> 2 | L34: =COUNTIF(Link_Project_Gap!$A$2:$A$112,$A34) -> 2 | M34: =IF($F34="",0,$F34) -> 0
A35: حل مراقبة الشبكة والرؤية التلقائية واستكشاف الأخطاء وإصلاحها | B35: البيانات | C35: GAP-D-04 | GAP-D-05 | GAP-T-5 | GAP-T-6 | D35: AR03 | E35: قيد التنفيذ | F35: 0.5 | G35: 45901 | H35: 46173 | I35: إدارة البيانات | K35: =COUNTIF(Link_Project_Req!$A$2:$A$68,$A35) -> 1 | L35: =COUNTIF(Link_Project_Gap!$A$2:$A$112,$A35) -> 4 | M35: =IF($F35="",0,$F35) -> 0.5
A36: حل تحسين أداء شبكة WAN | B36: التقنية | C36: GAP-T-11 | GAP-T-14 | GAP-T-17 | D36: TR02 | TR04 | E36: قيد التنفيذ | F36: 0.5 | G36: 45901 | H36: 46173 | I36: البنية التحتية والأمن السيبراني | K36: =COUNTIF(Link_Project_Req!$A$2:$A$68,$A36) -> 2 | L36: =COUNTIF(Link_Project_Gap!$A$2:$A$112,$A36) -> 3 | M36: =IF($F36="",0,$F36) -> 0.5
A37: خدمات الطباعة | E37: لم يبدأ | F37: 0 | G37: 46023 | H37: 46387 | I37: الإدارة العامة لتقنية المعلومات | K37: =COUNTIF(Link_Project_Req!$A$2:$A$68,$A37) -> 0 | L37: =COUNTIF(Link_Project_Gap!$A$2:$A$112,$A37) -> 0 | M37: =IF($F37="",0,$F37) -> 0
A38: حل تخزين السجلات | E38: قيد التنفيذ | F38: 0.5 | G38: 45901 | H38: 46173 | I38: الإدارة العامة لتقنية المعلومات | K38: =COUNTIF(Link_Project_Req!$A$2:$A$68,$A38) -> 0 | L38: =COUNTIF(Link_Project_Gap!$A$2:$A$112,$A38) -> 0 | M38: =IF($F38="",0,$F38) -> 0.5
A39: اجهزة حاسب | E39: لم يبدأ | F39: 0 | G39: 46023 | H39: 46387 | I39: الإدارة العامة لتقنية المعلومات | K39: =COUNTIF(Link_Project_Req!$A$2:$A$68,$A39) -> 0 | L39: =COUNTIF(Link_Project_Gap!$A$2:$A$112,$A39) -> 0 | M39: =IF($F39="",0,$F39) -> 0
A40: تجهيز البنية التحتية لمقرات المحوسبة | E40: لم يبدأ | F40: 0 | G40: 46023 | H40: 46387 | I40: الإدارة العامة لتقنية المعلومات | K40: =COUNTIF(Link_Project_Req!$A$2:$A$68,$A40) -> 0 | L40: =COUNTIF(Link_Project_Gap!$A$2:$A$112,$A40) -> 0 | M40: =IF($F40="",0,$F40) -> 0
...

Sheet متابعة المتطلبات
A1: رمز المتطلب | B1: وصف المتطلب | C1: طبقة/مجال المتطلب | D1: مصدر المتطلب | E1: أولوية التنفيذ | F1: مدى الصعوبة | G1: مرجع الوضع المستقبلي (To-Be) | H1: أهداف البنية المؤسسية | I1: الفجوات المرتبطة (GAP-*) | J1: المشاريع المرتبطة | K1: نسبة إغلاق المتطلب (محسوبة من المشاريع) | L1: حالة إغلاق المتطلب | M1: حالة المتطلب/التنفيذ | N1: المالك | O1: تاريخ آخر تحديث
A2: BR01 | B2: إعادة هندسة الإجراءات الخاصة بإدارة التغيير على العمليات مع وضع حوكمة فعالة، مع اعتبار الية لمراجعة وتحديث إجراءات الأعمال ونماذجها | C2: الأعمال | D2: إدارة التميز المؤسسي | E2: مرتفع | F2: مرتفع | G2: إغلاق GAP-B-06 | GAP-B-13 | GAP-B-15 | H2: تعزيز الحوكمة المؤسسية، المواءمة الاستراتيجية | I2: GAP-B-06 | GAP-B-13 | GAP-B-15 | J2: تأسيس وتنفيذ وتشغيل البنية المؤسسية في هيئة تقويم التعليم و التدريب | تحقيق شهادات الجودة | K2: =IFERROR(AVERAGEIF(Link_Project_Req!$B$2:$B$68,$A2,Link_Project_Req!$C$2:$C$68),0) -> 0.375 | L2: =IF(K2=0,"لم يبدأ",IF(K2>=1,"مغلق","قيد التنفيذ")) -> قيد التنفيذ | M2: قيد التنفيذ | N2: إدارة التميز المؤسسي | O2: 46056
A3: BR02 | B3: استكمال أتمتة جميع الإجراءات المتبقية لضمان تكامل الخدمات وتحسين الكفاءة التشغيلية | C3: الأعمال | D3: إدارة التميز المؤسسي | E3: متوسط | F3: مرتفع | G3: إغلاق GAP-B-01 | GAP-A-07 | H3: تعزيز الكفاءة التشغيلية وكفاءة الانفاق، تمكين التحول الرقمي | I3: GAP-B-01 | GAP-A-07 | J3: تطوير نظامي اختبارات الطوارئ والاختبارات المؤسسية | النظام الشامل للاختبارات | K3: =IFERROR(AVERAGEIF(Link_Project_Req!$B$2:$B$68,$A3,Link_Project_Req!$C$2:$C$68),0) -> 0.44155 | L3: =IF(K3=0,"لم يبدأ",IF(K3>=1,"مغلق","قيد التنفيذ")) -> قيد التنفيذ | M3: قيد التنفيذ | N3: إدارة التميز المؤسسي | O3: 46056
A4: AR01 | B4: تطوير نظام تواصل داخلي فعال يقلل الاعتماد على البريد الإلكتروني ويزيد التعاون | C4: الأعمال | D4: إدارة التميز المؤسسي | E4: متدني | F4: متوسط | G4: إغلاق GAP-B-17 | GAP-A-05 | H4: تعزيز الكفاءة التشغيلية وكفاءة الانفاق، تمكين التحول الرقمي | I4: GAP-B-17 | GAP-A-05 | J4: مشروع دعم مايكروسوفت الموحد | K4: =IFERROR(AVERAGEIF(Link_Project_Req!$B$2:$B$68,$A4,Link_Project_Req!$C$2:$C$68),0) -> 0.7 | L4: =IF(K4=0,"لم يبدأ",IF(K4>=1,"مغلق","قيد التنفيذ")) -> قيد التنفيذ | M4: قيد التنفيذ | N4: الإدارة العامة لتقنية المعلومات | O4: 46056
A5: AR02 | B5: توفير نظام مركزي لمتابعة الأداء وتحليل البيانات | C5: الأعمال | D5: إدارة التميز المؤسسي | E5: متوسط | F5: متوسط | G5: إغلاق GAP-B-18 | H5: دعم اتخاذ القرارات | I5: GAP-B-18 | J5: توريد وتركيب أدوات ذكاء الأعمال والتحليلات المتقدمة | تشغيل وصيانة نظم البيانات والتكامل وذكاء الأعمال لمنافسة | K5: =IFERROR(AVERAGEIF(Link_Project_Req!$B$2:$B$68,$A5,Link_Project_Req!$C$2:$C$68),0) -> 0.525 | L5: =IF(K5=0,"لم يبدأ",IF(K5>=1,"مغلق","قيد التنفيذ")) -> قيد التنفيذ | M5: قيد التنفيذ | N5: الإدارة العامة لتقنية المعلومات | O5: 46056
A6: BR03 | B6: إعادة هندسة الإجراءات الخاصة بإدارة التواصل مع الجهات الحكومية المزودة للخدمات لضمان استمرارية الخدمة | C6: الأعمال | D6: التحليل الرباعي | E6: متوسط | F6: متوسط | G6: إغلاق GAP-B-17 | GAP-B-05 | H6: تعزيز الكفاءة التشغيلية وكفاءة الانفاق، تمكين التحول الرقمي | I6: GAP-B-17 | GAP-B-05 | J6: تطوير منصة موحدة مستقبلهم | المنصة الرقمية لمؤسسات التعليم والتدريب | K6: =IFERROR(AVERAGEIF(Link_Project_Req!$B$2:$B$68,$A6,Link_Project_Req!$C$2:$C$68),0) -> 0.2 | L6: =IF(K6=0,"لم يبدأ",IF(K6>=1,"مغلق","قيد التنفيذ")) -> قيد التنفيذ | M6: لم يبدأ | N6: إدارة التميز المؤسسي | O6: 46056
A7: TR01 | B7: تأمين آلية مصادقة موحدة تشمل التحقق الثنائي وكلمات المرور لتعزيز الأمان والفعالية | C7: التقنية | D7: التحليل الرباعي | E7: متوسط | F7: مرتفع | G7: إغلاق GAP-T-10 | H7: تعزيز الحوكمة المؤسسية | I7: GAP-T-10 | J7: تطبيق خدمة النفاذ الوطني الموحد في هيئة تقويم التعليم والتدريب | K7: =IFERROR(AVERAGEIF(Link_Project_Req!$B$2:$B$68,$A7,Link_Project_Req!$C$2:$C$68),0) -> 0.55 | L7: =IF(K7=0,"لم يبدأ",IF(K7>=1,"مغلق","قيد التنفيذ")) -> قيد التنفيذ | M7: قيد التنفيذ | N7: البنية التحتية والأمن السيبراني | O7: 46056
A8: AR03 | B8: توفير الية للإبلاغ عن حوادث سرقة البيانات، بالإضافة إلى توفير تدريبات منتظمة للموظفين حول كيفية التعامل مع مثل هذه الحوادث | C8: البيانات | D8: التحليل الرباعي | E8: متوسط | F8: مرتفع | G8: إغلاق GAP-D-04 | GAP-D-05 | GAP-T-5 | GAP-T-6 | H8: تعزيز الحوكمة المؤسسية | I8: GAP-D-04 | GAP-D-05 | GAP-T-5 | GAP-T-6 | J8: حل مراقبة الشبكة والرؤية التلقائية واستكشاف الأخطاء وإصلاحها | K8: =IFERROR(AVERAGEIF(Link_Project_Req!$B$2:$B$68,$A8,Link_Project_Req!$C$2:$C$68),0) -> 0.5 | L8: =IF(K8=0,"لم يبدأ",IF(K8>=1,"مغلق","قيد التنفيذ")) -> قيد التنفيذ | M8: قيد التنفيذ | N8: الإدارة العامة لتقنية المعلومات | O8: 46056
A9: AR04 | B9: اعتماد تقنيات متقدمة لتصنيف البيانات، مثل بعض أنظمة إدارة البيانات المؤسسية التي تدعم التصنيف التلقائي والذكي للبيانات | C9: البيانات | D9: التحليل الرباعي | E9: متوسط | F9: مرتفع | G9: إغلاق GAP-D-06 | GAP-T-7 | H9: تعزيز الحوكمة المؤسسية، تمكين التحول الرقمي | I9: GAP-D-06 | GAP-T-7 | J9: توريد وتركيب أدوات إدارة البيانات الوصفية والبيانات الرئيسية والمرجعية | K9: =IFERROR(AVERAGEIF(Link_Project_Req!$B$2:$B$68,$A9,Link_Project_Req!$C$2:$C$68),0) -> 0.4 | L9: =IF(K9=0,"لم يبدأ",IF(K9>=1,"مغلق","قيد التنفيذ")) -> قيد التنفيذ | M9: لم يبدأ | N9: الإدارة العامة لتقنية المعلومات | O9: 46056
A10: DR01 | B10: وضع معايير موحدة لجودة البيانات وتقديم تدريبات للموظفين لتحسين جودة البيانات والتقارير | C10: البيانات | D10: التحليل الرباعي | E10: متوسط | F10: متوسط | G10: إغلاق GAP-D-15 | GAP-D-07 | H10: دعم اتخاذ القرارات، تعزيز الحوكمة المؤسسية | I10: GAP-D-15 | GAP-D-07 | J10: رفع مستوى نضج تطبيق ممارسات إدارة البيانات | K10: =IFERROR(AVERAGEIF(Link_Project_Req!$B$2:$B$68,$A10,Link_Project_Req!$C$2:$C$68),0) -> 0 | L10: =IF(K10=0,"لم يبدأ",IF(K10>=1,"مغلق","قيد التنفيذ")) -> لم يبدأ | M10: قيد التنفيذ | N10: إدارة البيانات | O10: 46056
A11: AR05 | B11: اعتماد نظام لإدارة جودة البيانات يشمل تعريف البيانات والمؤشرات وتجنب تكرار التقارير | C11: البيانات | D11: التحليل الرباعي | E11: متوسط | F11: مرتفع | G11: إغلاق GAP-D-07 | GAP-T-8 | GAP-D-09 | H11: دعم اتخاذ القرارات، تعزيز الكفاءة التشغيلية وكفاءة الانفاق | I11: GAP-D-07 | GAP-T-8 | GAP-D-09 | J11: رفع مستوى نضج تطبيق ممارسات إدارة البيانات | K11: =IFERROR(AVERAGEIF(Link_Project_Req!$B$2:$B$68,$A11,Link_Project_Req!$C$2:$C$68),0) -> 0 | L11: =IF(K11=0,"لم يبدأ",IF(K11>=1,"مغلق","قيد التنفيذ")) -> لم يبدأ | M11: قيد التنفيذ | N11: الإدارة العامة لتقنية المعلومات | O11: 46056
A12: DR02 | B12: تطوير وتنفيذ إجراء موحد لتحديد البيانات الرئيسية والمرجعية وضمان تحديثه بانتظام | C12: البيانات | D12: التحليل الرباعي | E12: متوسط | F12: متوسط | G12: إغلاق GAP-D-16 | GAP-D-28 | H12: دعم اتخاذ القرارات، تعزيز الكفاءة التشغيلية وكفاءة الانفاق | I12: GAP-D-16 | GAP-D-28 | J12: توريد وتركيب أدوات إدارة البيانات الوصفية والبيانات الرئيسية والمرجعية | K12: =IFERROR(AVERAGEIF(Link_Project_Req!$B$2:$B$68,$A12,Link_Project_Req!$C$2:$C$68),0) -> 0.4 | L12: =IF(K12=0,"لم يبدأ",IF(K12>=1,"مغلق","قيد التنفيذ")) -> قيد التنفيذ | M12: لم يبدأ | N12: إدارة البيانات | O12: 46056
A13: AR06 | B13: تطوير نظام موحد لتجميع بيانات المستفيدين وتحسين تكامل البيانات بين الأنظمة المختلفة | C13: البيانات | D13: التحليل الرباعي | E13: متوسط | F13: مرتفع | G13: إغلاق GAP-D-10 | GAP-D-11 | GAP-D-31 | H13: دعم تحسين تجربة المستفيد، دعم اتخاذ القرارات | I13: GAP-D-10 | GAP-D-11 | GAP-D-31 | J13: المنصة الرقمية لمؤسسات التعليم والتدريب | تشغيل وصيانة نظم البيانات والتكامل وذكاء الأعمال لمنافسة | K13: =IFERROR(AVERAGEIF(Link_Project_Req!$B$2:$B$68,$A13,Link_Project_Req!$C$2:$C$68),0) -> 0.425 | L13: =IF(K13=0,"لم يبدأ",IF(K13>=1,"مغلق","قيد التنفيذ")) -> قيد التنفيذ | M13: قيد التنفيذ | N13: الإدارة العامة لتقنية المعلومات | O13: 46056
... A47: AR20 | B47: إنشاء نظام مركزي لإدارة المشاريع يتيح تعبئة النماذج مرة واحدة ومشاركتها عبر الإدارات | C47: الأعمال | D47: أخصائي الجودة للأعمال | E47: متوسط | F47: متوسط | G47: إغلاق GAP-B-70 | GAP-B-90 | H47: تعزيز الحوكمة المؤسسية، المواءمة الاستراتيجية | I47: GAP-B-70 | GAP-B-90 | J47: منصة ديجيتال اكس | K47: =IFERROR(AVERAGEIF(Link_Project_Req!$B$2:$B$68,$A47,Link_Project_Req!$C$2:$C$68),0) -> 0.45 | L47: =IF(K47=0,"لم يبدأ",IF(K47>=1,"مغلق","قيد التنفيذ")) -> قيد التنفيذ | M47: لم يبدأ | N47: الإدارة العامة لتقنية المعلومات | O47: 46056

Sheet الفجوات
A1: رمز الفجوة | B1: النص | C1: المجال | D1: المتطلبات المرتبطة (BR/AR/DR/TR) | E1: المشاريع المرتبطة | F1: نسبة إغلاق الفجوة (محسوبة من المشاريع/المتطلبات) | G1: منهجية الحساب | H1: ملاحظات
A2: GAP-B-01 | B2: غياب الأتمتة لبعض الخدمات أو الإجراءات الأساسية والداعمة | C2: فجوات بنية الأعمال | D2: BR02 | E2: النظام الشامل للاختبارات | تطوير نظامي اختبارات الطوارئ والاختبارات المؤسسية | F2: =IF(COUNTIF(Link_Project_Gap!$B$2:$B$112,$A2)>0,IFERROR(AVERAGEIF(Link_Project_Gap!$B$2:$B$112,$A2,Link_Project_Gap!$C$2:$C$112),0),IFERROR(AVERAGEIF(Link_Gap_Req!$A$2:$A$79,$A2,Link_Gap_Req!$C$2:$C$79),0)) -> 0.44155 | G2: =IF(COUNTIF(Link_Project_Gap!$B$2:$B$112,$A2)>0,"من المشاريع",IF(COUNTIF(Link_Gap_Req!$A$2:$A$79,$A2)>0,"من المتطلبات","لا يوجد ربط")) -> من المشاريع
A3: GAP-B-02 | B3: ضعف في تطبيق اتفاقيات مستوى الخدمة أو التشغيل (SLA , OLA) على عدد معين من الخدمات سواء بشكل جزئي أو كلي | C3: فجوات بنية الأعمال | D3: BR13 | E3: تأسيس وتنفيذ وتشغيل البنية المؤسسية في هيئة تقويم التعليم و التدريب | تحقيق شهادات الجودة | F3: =IF(COUNTIF(Link_Project_Gap!$B$2:$B$112,$A3)>0,IFERROR(AVERAGEIF(Link_Project_Gap!$B$2:$B$112,$A3,Link_Project_Gap!$C$2:$C$112),0),IFERROR(AVERAGEIF(Link_Gap_Req!$A$2:$A$79,$A3,Link_Gap_Req!$C$2:$C$79),0)) -> 0.375 | G3: =IF(COUNTIF(Link_Project_Gap!$B$2:$B$112,$A3)>0,"من المشاريع",IF(COUNTIF(Link_Gap_Req!$A$2:$A$79,$A3)>0,"من المتطلبات","لا يوجد ربط")) -> من المشاريع
A4: GAP-B-03 | B4: الحاجة إلى تمكين / تفعيل خاصية الاعتماد الإلكتروني في عدد من الخدمات | C4: فجوات بنية الأعمال | F4: =IF(COUNTIF(Link_Project_Gap!$B$2:$B$112,$A4)>0,IFERROR(AVERAGEIF(Link_Project_Gap!$B$2:$B$112,$A4,Link_Project_Gap!$C$2:$C$112),0),IFERROR(AVERAGEIF(Link_Gap_Req!$A$2:$A$79,$A4,Link_Gap_Req!$C$2:$C$79),0)) -> 0 | G4: =IF(COUNTIF(Link_Project_Gap!$B$2:$B$112,$A4)>0,"من المشاريع",IF(COUNTIF(Link_Gap_Req!$A$2:$A$79,$A4)>0,"من المتطلبات","لا يوجد ربط")) -> لا يوجد ربط
A5: GAP-B-04 | B5: الحاجة إلى تمكين تتبع حالة الطلبات في بعض الخدمات و توحيد طريقة إرسال الإشعارات | C5: فجوات بنية الأعمال | D5: BR04 | E5: المساعد الرقمي للعناية بالمستفيدين | المنصة الرقمية لمؤسسات التعليم والتدريب | F5: =IF(COUNTIF(Link_Project_Gap!$B$2:$B$112,$A5)>0,IFERROR(AVERAGEIF(Link_Project_Gap!$B$2:$B$112,$A5,Link_Project_Gap!$C$2:$C$112),0),IFERROR(AVERAGEIF(Link_Gap_Req!$A$2:$A$79,$A5,Link_Gap_Req!$C$2:$C$79),0)) -> 0.1 | G5: =IF(COUNTIF(Link_Project_Gap!$B$2:$B$112,$A5)>0,"من المشاريع",IF(COUNTIF(Link_Gap_Req!$A$2:$A$79,$A5)>0,"من المتطلبات","لا يوجد ربط")) -> من المشاريع
A6: GAP-B-05 | B6: الحاجة إلى التكامل مع الأنظمة والمنصات الداخلية و الخارجية في عدد من الخدمات أو الإجراءات | C6: فجوات بنية الأعمال | D6: AR18 | BR03 | BR04 | E6: الخدمات الاستشارية المدارة لتعزيز إدارة دورة حياة البرمجيات | المساعد الرقمي للعناية بالمستفيدين | المنصة الرقمية لمؤسسات التعليم والتدريب | تطوير تطبيق ومنصة مستقبلهم | F6: =IF(COUNTIF(Link_Project_Gap!$B$2:$B$112,$A6)>0,IFERROR(AVERAGEIF(Link_Project_Gap!$B$2:$B$112,$A6,Link_Project_Gap!$C$2:$C$112),0),IFERROR(AVERAGEIF(Link_Gap_Req!$A$2:$A$79,$A6,Link_Gap_Req!$C$2:$C$79),0)) -> 0.066666667 | G6: =IF(COUNTIF(Link_Project_Gap!$B$2:$B$112,$A6)>0,"من المشاريع",IF(COUNTIF(Link_Gap_Req!$A$2:$A$79,$A6)>0,"من المتطلبات","لا يوجد ربط")) -> من المشاريع
A7: GAP-B-06 | B7: غياب عملية حوكمة متكاملة لإجراءات الأعمال بشكل فعال | C7: فجوات بنية الأعمال | D7: AR17 | BR01 | BR18 | E7: تأسيس وتنفيذ وتشغيل البنية المؤسسية في هيئة تقويم التعليم و التدريب | تحقيق شهادات الجودة | F7: =IF(COUNTIF(Link_Project_Gap!$B$2:$B$112,$A7)>0,IFERROR(AVERAGEIF(Link_Project_Gap!$B$2:$B$112,$A7,Link_Project_Gap!$C$2:$C$112),0),IFERROR(AVERAGEIF(Link_Gap_Req!$A$2:$A$79,$A7,Link_Gap_Req!$C$2:$C$79),0)) -> 0.375 | G7: =IF(COUNTIF(Link_Project_Gap!$B$2:$B$112,$A7)>0,"من المشاريع",IF(COUNTIF(Link_Gap_Req!$A$2:$A$79,$A7)>0,"من المتطلبات","لا يوجد ربط")) -> من المشاريع
A8: GAP-B-07 | B8: الحاجة إلى تطوير وتحسين مؤشرات قياس أداء لبعض الخدمات / الإجراءات | C8: فجوات بنية الأعمال | D8: AR11 | BR12 | BR15 | E8: توريد وتركيب أدوات ذكاء الأعمال والتحليلات المتقدمة | F8: =IF(COUNTIF(Link_Project_Gap!$B$2:$B$112,$A8)>0,IFERROR(AVERAGEIF(Link_Project_Gap!$B$2:$B$112,$A8,Link_Project_Gap!$C$2:$C$112),0),IFERROR(AVERAGEIF(Link_Gap_Req!$A$2:$A$79,$A8,Link_Gap_Req!$C$2:$C$79),0)) -> 0.4 | G8: =IF(COUNTIF(Link_Project_Gap!$B$2:$B$112,$A8)>0,"من المشاريع",IF(COUNTIF(Link_Gap_Req!$A$2:$A$79,$A8)>0,"من المتطلبات","لا يوجد ربط")) -> من المشاريع
A9: GAP-B-08 | B9: يوجد نماذج موحدة لتوثيق إجراءات العمل (أدلة الأعمال الإجرائية) ولكنها تحتاج إلى مراجعة وتحديث بانتظام لضمان توافقها مع التغيرات والاحتياجات الجديدة | C9: فجوات بنية الأعمال | F9: =IF(COUNTIF(Link_Project_Gap!$B$2:$B$112,$A9)>0,IFERROR(AVERAGEIF(Link_Project_Gap!$B$2:$B$112,$A9,Link_Project_Gap!$C$2:$C$112),0),IFERROR(AVERAGEIF(Link_Gap_Req!$A$2:$A$79,$A9,Link_Gap_Req!$C$2:$C$79),0)) -> 0 | G9: =IF(COUNTIF(Link_Project_Gap!$B$2:$B$112,$A9)>0,"من المشاريع",IF(COUNTIF(Link_Gap_Req!$A$2:$A$79,$A9)>0,"من المتطلبات","لا يوجد ربط")) -> لا يوجد ربط
A10: GAP-B-09 | B10: الحاجة إلى توفير (أدلة الخدمات، أدلة مرئية ) للمستفيدين بشكل متكامل ومفصّل وموحد لعدد من الخدمات الخدمات | C10: فجوات بنية الأعمال | F10: =IF(COUNTIF(Link_Project_Gap!$B$2:$B$112,$A10)>0,IFERROR(AVERAGEIF(Link_Project_Gap!$B$2:$B$112,$A10,Link_Project_Gap!$C$2:$C$112),0),IFERROR(AVERAGEIF(Link_Gap_Req!$A$2:$A$79,$A10,Link_Gap_Req!$C$2:$C$79),0)) -> 0 | G10: =IF(COUNTIF(Link_Project_Gap!$B$2:$B$112,$A10)>0,"من المشاريع",IF(COUNTIF(Link_Gap_Req!$A$2:$A$79,$A10)>0,"من المتطلبات","لا يوجد ربط")) -> لا يوجد ربط
A11: GAP-B-10 | B11: الحاجة إلى توفير نماذج الحوكمة والقياس بشكل كامل | C11: فجوات بنية الأعمال | D11: BR20 | E11: تأسيس وتنفيذ وتشغيل البنية المؤسسية في هيئة تقويم التعليم و التدريب | F11: =IF(COUNTIF(Link_Project_Gap!$B$2:$B$112,$A11)>0,IFERROR(AVERAGEIF(Link_Project_Gap!$B$2:$B$112,$A11,Link_Project_Gap!$C$2:$C$112),0),IFERROR(AVERAGEIF(Link_Gap_Req!$A$2:$A$79,$A11,Link_Gap_Req!$C$2:$C$79),0)) -> 0.75 | G11: =IF(COUNTIF(Link_Project_Gap!$B$2:$B$112,$A11)>0,"من المشاريع",IF(COUNTIF(Link_Gap_Req!$A$2:$A$79,$A11)>0,"من المتطلبات","لا يوجد ربط")) -> من المشاريع
A12: GAP-B-11 | B12: ضرورة استكمال وتحسين بعض التقارير الإلكترونية الحالية التي تحتاج إلى استكمال وتحسين | C12: فجوات بنية الأعمال | F12: =IF(COUNTIF(Link_Project_Gap!$B$2:$B$112,$A12)>0,IFERROR(AVERAGEIF(Link_Project_Gap!$B$2:$B$112,$A12,Link_Project_Gap!$C$2:$C$112),0),IFERROR(AVERAGEIF(Link_Gap_Req!$A$2:$A$79,$A12,Link_Gap_Req!$C$2:$C$79),0)) -> 0 | G12: =IF(COUNTIF(Link_Project_Gap!$B$2:$B$112,$A12)>0,"من المشاريع",IF(COUNTIF(Link_Gap_Req!$A$2:$A$79,$A12)>0,"من المتطلبات","لا يوجد ربط")) -> لا يوجد ربط
A13: GAP-B-12 | B13: تنفذ بعض الأعمال حاليا باستخدام برمجيات لمعالجة البيانات | C13: فجوات بنية الأعمال | F13: =IF(COUNTIF(Link_Project_Gap!$B$2:$B$112,$A13)>0,IFERROR(AVERAGEIF(Link_Project_Gap!$B$2:$B$112,$A13,Link_Project_Gap!$C$2:$C$112),0),IFERROR(AVERAGEIF(Link_Gap_Req!$A$2:$A$79,$A13,Link_Gap_Req!$C$2:$C$79),0)) -> 0 | G13: =IF(COUNTIF(Link_Project_Gap!$B$2:$B$112,$A13)>0,"من المشاريع",IF(COUNTIF(Link_Gap_Req!$A$2:$A$79,$A13)>0,"من المتطلبات","لا يوجد ربط")) -> لا يوجد ربط
A14: GAP-B-13 | B14: ضرورة إعادة هندسة الإجراءات التي تحتاج إلى تحسين | C14: فجوات بنية الأعمال | D14: BR01 | E14: تأسيس وتنفيذ وتشغيل البنية المؤسسية في هيئة تقويم التعليم و التدريب | تحقيق شهادات الجودة | F14: =IF(COUNTIF(Link_Project_Gap!$B$2:$B$112,$A14)>0,IFERROR(AVERAGEIF(Link_Project_Gap!$B$2:$B$112,$A14,Link_Project_Gap!$C$2:$C$112),0),IFERROR(AVERAGEIF(Link_Gap_Req!$A$2:$A$79,$A14,Link_Gap_Req!$C$2:$C$79),0)) -> 0.375 | G14: =IF(COUNTIF(Link_Project_Gap!$B$2:$B$112,$A14)>0,"من المشاريع",IF(COUNTIF(Link_Gap_Req!$A$2:$A$79,$A14)>0,"من المتطلبات","لا يوجد ربط")) -> من المشاريع
A15: GAP-B-14 | B15: ضرورة تطوير وتنفيذ برامج تدريبية شاملة وفعالة للموظفين لتعزيز المهارات الرقمية كجزء من التحسين المستمر | C15: فجوات بنية الأعمال | D15: BR05 | BR06 | BR07 | E15: تحقيق شهادات الجودة | تفعيل الابتكار الرقمي | مشروع دعم مايكروسوفت الموحد | F15: =IF(COUNTIF(Link_Project_Gap!$B$2:$B$112,$A15)>0,IFERROR(AVERAGEIF(Link_Project_Gap!$B$2:$B$112,$A15,Link_Project_Gap!$C$2:$C$112),0),IFERROR(AVERAGEIF(Link_Gap_Req!$A$2:$A$79,$A15,Link_Gap_Req!$C$2:$C$79),0)) -> 0.23333333 | G15: =IF(COUNTIF(Link_Project_Gap!$B$2:$B$112,$A15)>0,"من المشاريع",IF(COUNTIF(Link_Gap_Req!$A$2:$A$79,$A15)>0,"من المتطلبات","لا يوجد ربط")) -> من المشاريع
A16: GAP-B-15 | B16: ضرورة تطوير وتطبيق نموذج متعدد القنوات لدمج جميع قنوات التواصل مع المستفيدين لتحقيق تجربة مستفيدين سلسة | C16: فجوات بنية الأعمال | D16: BR01 | BR17 | E16: تأسيس وتنفيذ وتشغيل البنية المؤسسية في هيئة تقويم التعليم و التدريب | تحقيق شهادات الجودة | F16: =IF(COUNTIF(Link_Project_Gap!$B$2:$B$112,$A16)>0,IFERROR(AVERAGEIF(Link_Project_Gap!$B$2:$B$112,$A16,Link_Project_Gap!$C$2:$C$112),0),IFERROR(AVERAGEIF(Link_Gap_Req!$A$2:$A$79,$A16,Link_Gap_Req!$C$2:$C$79),0)) -> 0.375 | G16: =IF(COUNTIF(Link_Project_Gap!$B$2:$B$112,$A16)>0,"من المشاريع",IF(COUNTIF(Link_Gap_Req!$A$2:$A$79,$A16)>0,"من المتطلبات","لا يوجد ربط")) -> من المشاريع
A17: GAP-B-16 | B17: الاعتماد على التواصل اليدوي والتصعيد اليدوي | C17: فجوات بنية الأعمال | D17: AR19 | BR19 | E17: المنصة الرقمية لمؤسسات التعليم والتدريب | مشروع دعم مايكروسوفت الموحد | F17: =IF(COUNTIF(Link_Project_Gap!$B$2:$B$112,$A17)>0,IFERROR(AVERAGEIF(Link_Project_Gap!$B$2:$B$112,$A17,Link_Project_Gap!$C$2:$C$112),0),IFERROR(AVERAGEIF(Link_Gap_Req!$A$2:$A$79,$A17,Link_Gap_Req!$C$2:$C$79),0)) -> 0.45 | G17: =IF(COUNTIF(Link_Project_Gap!$B$2:$B$112,$A17)>0,"من المشاريع",IF(COUNTIF(Link_Gap_Req!$A$2:$A$79,$A17)>0,"من المتطلبات","لا يوجد ربط")) -> من المشاريع
A18: GAP-B-17 | B18: الحاجة إلى تحسين تجربة المستفيد ورحلاته المختلفة | C18: فجوات بنية الأعمال | D18: AR01 | BR03 | BR04 | E18: المساعد الرقمي للعناية بالمستفيدين | المنصة الرقمية لمؤسسات التعليم والتدريب | تطوير تطبيق ومنصة مستقبلهم | مشروع دعم مايكروسوفت الموحد | F18: =IF(COUNTIF(Link_Project_Gap!$B$2:$B$112,$A18)>0,IFERROR(AVERAGEIF(Link_Project_Gap!$B$2:$B$112,$A18,Link_Project_Gap!$C$2:$C$112),0),IFERROR(AVERAGEIF(Link_Gap_Req!$A$2:$A$79,$A18,Link_Gap_Req!$C$2:$C$79),0)) -> 0.3 | G18: =IF(COUNTIF(Link_Project_Gap!$B$2:$B$112,$A18)>0,"من المشاريع",IF(COUNTIF(Link_Gap_Req!$A$2:$A$79,$A18)>0,"من المتطلبات","لا يوجد ربط")) -> من المشاريع
